supervisor: couldn't exec /var/www/django/test.sh: EACCES
supervisor: child process was not spawned
supervisor: couldn't exec /var/www/django/test.sh: EACCES
supervisor: child process was not spawned
supervisor: couldn't exec /var/www/django/test.sh: EACCES
supervisor: child process was not spawned
supervisor: couldn't exec /var/www/django/test.sh: EACCES
supervisor: child process was not spawned
[06/Oct/2017 13:04:15] "GET / HTTP/1.1" 200 1716
Not Found: /favicon.ico
[06/Oct/2017 13:04:16] "GET /favicon.ico HTTP/1.1" 404 1966
[06/Oct/2017 13:04:53] "GET / HTTP/1.1" 200 1716
Not Found: /favicon.ico
[06/Oct/2017 13:04:53] "GET /favicon.ico HTTP/1.1" 404 1966
usage: gunicorn [OPTIONS] [APP_MODULE]
gunicorn: error: No application module specified.
usage: gunicorn [OPTIONS] [APP_MODULE]
gunicorn: error: No application module specified.
usage: gunicorn [OPTIONS] [APP_MODULE]
gunicorn: error: No application module specified.
usage: gunicorn [OPTIONS] [APP_MODULE]
gunicorn: error: No application module specified.
[09/Oct/2017 08:23:21] "GET / HTTP/1.1" 200 1716
Not Found: /favicon.ico
[09/Oct/2017 08:23:21] "GET /favicon.ico HTTP/1.1" 404 1966
Invalid HTTP_HOST header: 'django-test.mcad.local:8000'. You may need to add 'django-test.mcad.local' to ALLOWED_HOSTS.
[09/Oct/2017 08:23:35] "GET / HTTP/1.1" 400 58509
Invalid HTTP_HOST header: 'django-test.mcad.local:8000'. You may need to add 'django-test.mcad.local' to ALLOWED_HOSTS.
[09/Oct/2017 08:23:35] "GET /favicon.ico HTTP/1.1" 400 58600
Invalid HTTP_HOST header: 'django-test.mcad.local:8000'. You may need to add 'django-test.mcad.local' to ALLOWED_HOSTS.
[09/Oct/2017 08:23:37] "GET / HTTP/1.1" 400 58770
Invalid HTTP_HOST header: 'django-test.mcad.local:8000'. You may need to add 'django-test.mcad.local' to ALLOWED_HOSTS.
[09/Oct/2017 08:23:37] "GET /favicon.ico HTTP/1.1" 400 58861
Invalid HTTP_HOST header: 'django-test.mcad.local:8000'. You may need to add 'django-test.mcad.local' to ALLOWED_HOSTS.
[09/Oct/2017 08:23:38] "GET / HTTP/1.1" 400 58770
Invalid HTTP_HOST header: 'django-test.mcad.local:8000'. You may need to add 'django-test.mcad.local' to ALLOWED_HOSTS.
[09/Oct/2017 08:23:38] "GET /favicon.ico HTTP/1.1" 400 58861
[09/Oct/2017 08:23:42] "GET / HTTP/1.1" 200 1716
Not Found: /favicon.ico
[09/Oct/2017 08:23:43] "GET /favicon.ico HTTP/1.1" 404 1966
Invalid HTTP_HOST header: 'django-test.mcad.local:8000'. You may need to add 'django-test.mcad.local' to ALLOWED_HOSTS.
[09/Oct/2017 08:23:50] "GET / HTTP/1.1" 400 58509
Invalid HTTP_HOST header: 'django-test.mcad.local:8000'. You may need to add 'django-test.mcad.local' to ALLOWED_HOSTS.
[09/Oct/2017 08:23:51] "GET /favicon.ico HTTP/1.1" 400 58600
Performing system checks...

System check identified no issues (0 silenced).
October 09, 2017 - 08:23:20
Django version 1.11.6, using settings 'mysite.settings'
Starting development server at http://192.168.1.123:8000/
Quit the server with CONTROL-C.
[09/Oct/2017 08:57:51] "GET / HTTP/1.1" 200 1716
Not Found: /favicon.ico
[09/Oct/2017 08:57:52] "GET /favicon.ico HTTP/1.1" 404 1975
[09/Oct/2017 08:57:56] "GET / HTTP/1.1" 200 1716
Not Found: /favicon.ico
[09/Oct/2017 08:57:57] "GET /favicon.ico HTTP/1.1" 404 1975
[09/Oct/2017 08:57:57] "GET / HTTP/1.1" 200 1716
Performing system checks...

System check identified no issues (0 silenced).
October 09, 2017 - 08:57:51
Django version 1.11.6, using settings 'mysite.settings'
Starting development server at http://192.168.1.123:8000/
Quit the server with CONTROL-C.
[09/Oct/2017 09:04:38] "GET / HTTP/1.1" 200 1716
[09/Oct/2017 09:04:39] "GET / HTTP/1.1" 200 1716
[09/Oct/2017 09:04:46] "GET /admin HTTP/1.1" 301 0
[09/Oct/2017 09:04:46] "GET /admin/ HTTP/1.1" 302 0
[09/Oct/2017 09:04:46] "GET /admin/login/?next=/admin/ HTTP/1.1" 200 1654
[09/Oct/2017 09:04:46] "GET /static/admin/css/login.css HTTP/1.1" 200 1203
[09/Oct/2017 09:04:46] "GET /static/admin/css/base.css HTTP/1.1" 200 16066
[09/Oct/2017 09:04:46] "GET /static/admin/css/fonts.css HTTP/1.1" 200 423
[09/Oct/2017 09:04:46] "GET /static/admin/fonts/Roboto-Regular-webfont.woff HTTP/1.1" 200 80304
[09/Oct/2017 09:04:47] "GET /static/admin/fonts/Roboto-Light-webfont.woff HTTP/1.1" 200 81348
Internal Server Error: /admin/login/
Traceback (most recent call last):
  File "/var/www/django/myvenv/lib/python3.4/site-packages/django/db/backends/utils.py", line 65, in execute
    return self.cursor.execute(sql, params)
  File "/var/www/django/myvenv/lib/python3.4/site-packages/django/db/backends/sqlite3/base.py", line 328, in execute
    return Database.Cursor.execute(self, query, params)
sqlite3.OperationalError: attempt to write a readonly database

The above exception was the direct cause of the following exception:

Traceback (most recent call last):
  File "/var/www/django/myvenv/lib/python3.4/site-packages/django/core/handlers/exception.py", line 41, in inner
    response = get_response(request)
  File "/var/www/django/myvenv/lib/python3.4/site-packages/django/core/handlers/base.py", line 249, in _legacy_get_response
    response = self._get_response(request)
  File "/var/www/django/myvenv/lib/python3.4/site-packages/django/core/handlers/base.py", line 187, in _get_response
    response = self.process_exception_by_middleware(e, request)
  File "/var/www/django/myvenv/lib/python3.4/site-packages/django/core/handlers/base.py", line 185, in _get_response
    response = wrapped_callback(request, *callback_args, **callback_kwargs)
  File "/var/www/django/myvenv/lib/python3.4/site-packages/django/views/decorators/cache.py", line 57, in _wrapped_view_func
    response = view_func(request, *args, **kwargs)
  File "/var/www/django/myvenv/lib/python3.4/site-packages/django/contrib/admin/sites.py", line 393, in login
    return LoginView.as_view(**defaults)(request)
  File "/var/www/django/myvenv/lib/python3.4/site-packages/django/views/generic/base.py", line 68, in view
    return self.dispatch(request, *args, **kwargs)
  File "/var/www/django/myvenv/lib/python3.4/site-packages/django/utils/decorators.py", line 67, in _wrapper
    return bound_func(*args, **kwargs)
  File "/var/www/django/myvenv/lib/python3.4/site-packages/django/views/decorators/debug.py", line 76, in sensitive_post_parameters_wrapper
    return view(request, *args, **kwargs)
  File "/var/www/django/myvenv/lib/python3.4/site-packages/django/utils/decorators.py", line 63, in bound_func
    return func.__get__(self, type(self))(*args2, **kwargs2)
  File "/var/www/django/myvenv/lib/python3.4/site-packages/django/utils/decorators.py", line 67, in _wrapper
    return bound_func(*args, **kwargs)
  File "/var/www/django/myvenv/lib/python3.4/site-packages/django/utils/decorators.py", line 149, in _wrapped_view
    response = view_func(request, *args, **kwargs)
  File "/var/www/django/myvenv/lib/python3.4/site-packages/django/utils/decorators.py", line 63, in bound_func
    return func.__get__(self, type(self))(*args2, **kwargs2)
  File "/var/www/django/myvenv/lib/python3.4/site-packages/django/utils/decorators.py", line 67, in _wrapper
    return bound_func(*args, **kwargs)
  File "/var/www/django/myvenv/lib/python3.4/site-packages/django/views/decorators/cache.py", line 57, in _wrapped_view_func
    response = view_func(request, *args, **kwargs)
  File "/var/www/django/myvenv/lib/python3.4/site-packages/django/utils/decorators.py", line 63, in bound_func
    return func.__get__(self, type(self))(*args2, **kwargs2)
  File "/var/www/django/myvenv/lib/python3.4/site-packages/django/contrib/auth/views.py", line 90, in dispatch
    return super(LoginView, self).dispatch(request, *args, **kwargs)
  File "/var/www/django/myvenv/lib/python3.4/site-packages/django/views/generic/base.py", line 88, in dispatch
    return handler(request, *args, **kwargs)
  File "/var/www/django/myvenv/lib/python3.4/site-packages/django/views/generic/edit.py", line 183, in post
    return self.form_valid(form)
  File "/var/www/django/myvenv/lib/python3.4/site-packages/django/contrib/auth/views.py", line 119, in form_valid
    auth_login(self.request, form.get_user())
  File "/var/www/django/myvenv/lib/python3.4/site-packages/django/contrib/auth/__init__.py", line 139, in login
    request.session.cycle_key()
  File "/var/www/django/myvenv/lib/python3.4/site-packages/django/contrib/sessions/backends/base.py", line 311, in cycle_key
    self.create()
  File "/var/www/django/myvenv/lib/python3.4/site-packages/django/contrib/sessions/backends/db.py", line 54, in create
    self.save(must_create=True)
  File "/var/www/django/myvenv/lib/python3.4/site-packages/django/contrib/sessions/backends/db.py", line 87, in save
    obj.save(force_insert=must_create, force_update=not must_create, using=using)
  File "/var/www/django/myvenv/lib/python3.4/site-packages/django/db/models/base.py", line 808, in save
    force_update=force_update, update_fields=update_fields)
  File "/var/www/django/myvenv/lib/python3.4/site-packages/django/db/models/base.py", line 838, in save_base
    updated = self._save_table(raw, cls, force_insert, force_update, using, update_fields)
  File "/var/www/django/myvenv/lib/python3.4/site-packages/django/db/models/base.py", line 924, in _save_table
    result = self._do_insert(cls._base_manager, using, fields, update_pk, raw)
  File "/var/www/django/myvenv/lib/python3.4/site-packages/django/db/models/base.py", line 963, in _do_insert
    using=using, raw=raw)
  File "/var/www/django/myvenv/lib/python3.4/site-packages/django/db/models/manager.py", line 85, in manager_method
    return getattr(self.get_queryset(), name)(*args, **kwargs)
  File "/var/www/django/myvenv/lib/python3.4/site-packages/django/db/models/query.py", line 1076, in _insert
    return query.get_compiler(using=using).execute_sql(return_id)
  File "/var/www/django/myvenv/lib/python3.4/site-packages/django/db/models/sql/compiler.py", line 1107, in execute_sql
    cursor.execute(sql, params)
  File "/var/www/django/myvenv/lib/python3.4/site-packages/django/db/backends/utils.py", line 80, in execute
    return super(CursorDebugWrapper, self).execute(sql, params)
  File "/var/www/django/myvenv/lib/python3.4/site-packages/django/db/backends/utils.py", line 65, in execute
    return self.cursor.execute(sql, params)
  File "/var/www/django/myvenv/lib/python3.4/site-packages/django/db/utils.py", line 94, in __exit__
    six.reraise(dj_exc_type, dj_exc_value, traceback)
  File "/var/www/django/myvenv/lib/python3.4/site-packages/django/utils/six.py", line 685, in reraise
    raise value.with_traceback(tb)
  File "/var/www/django/myvenv/lib/python3.4/site-packages/django/db/backends/utils.py", line 65, in execute
    return self.cursor.execute(sql, params)
  File "/var/www/django/myvenv/lib/python3.4/site-packages/django/db/backends/sqlite3/base.py", line 328, in execute
    return Database.Cursor.execute(self, query, params)
django.db.utils.OperationalError: attempt to write a readonly database
[09/Oct/2017 09:06:50] "POST /admin/login/?next=/admin/ HTTP/1.1" 500 225329
[09/Oct/2017 09:06:55] "GET /admin/login/?next=/admin/ HTTP/1.1" 200 1654
[09/Oct/2017 09:06:57] "GET /admin/login/?next=/admin/ HTTP/1.1" 200 1654
[09/Oct/2017 09:06:57] "GET /static/admin/css/login.css HTTP/1.1" 200 1203
[09/Oct/2017 09:06:57] "GET /static/admin/css/base.css HTTP/1.1" 200 16066
[09/Oct/2017 09:06:57] "GET /static/admin/css/fonts.css HTTP/1.1" 200 423
[09/Oct/2017 09:06:57] "GET /static/admin/fonts/Roboto-Regular-webfont.woff HTTP/1.1" 200 80304
[09/Oct/2017 09:06:57] "GET /static/admin/fonts/Roboto-Light-webfont.woff HTTP/1.1" 200 81348
Not Found: /favicon.ico
[09/Oct/2017 09:06:57] "GET /favicon.ico HTTP/1.1" 404 1975
[09/Oct/2017 09:07:00] "GET /admin/ HTTP/1.1" 302 0
[09/Oct/2017 09:07:00] "GET /admin/login/?next=/admin/ HTTP/1.1" 200 1654
[09/Oct/2017 09:07:01] "GET /admin/login/?next=/admin/ HTTP/1.1" 200 1654
[09/Oct/2017 09:07:01] "GET /static/admin/css/base.css HTTP/1.1" 200 16066
[09/Oct/2017 09:07:01] "GET /static/admin/css/login.css HTTP/1.1" 200 1203
[09/Oct/2017 09:07:01] "GET /static/admin/css/fonts.css HTTP/1.1" 200 423
[09/Oct/2017 09:07:01] "GET /static/admin/fonts/Roboto-Regular-webfont.woff HTTP/1.1" 200 80304
[09/Oct/2017 09:07:01] "GET /static/admin/fonts/Roboto-Light-webfont.woff HTTP/1.1" 200 81348
Not Found: /favicon.ico
[09/Oct/2017 09:07:01] "GET /favicon.ico HTTP/1.1" 404 1975
Internal Server Error: /admin/login/
Traceback (most recent call last):
  File "/var/www/django/myvenv/lib/python3.4/site-packages/django/db/backends/utils.py", line 65, in execute
    return self.cursor.execute(sql, params)
  File "/var/www/django/myvenv/lib/python3.4/site-packages/django/db/backends/sqlite3/base.py", line 328, in execute
    return Database.Cursor.execute(self, query, params)
sqlite3.OperationalError: attempt to write a readonly database

The above exception was the direct cause of the following exception:

Traceback (most recent call last):
  File "/var/www/django/myvenv/lib/python3.4/site-packages/django/core/handlers/exception.py", line 41, in inner
    response = get_response(request)
  File "/var/www/django/myvenv/lib/python3.4/site-packages/django/core/handlers/base.py", line 249, in _legacy_get_response
    response = self._get_response(request)
  File "/var/www/django/myvenv/lib/python3.4/site-packages/django/core/handlers/base.py", line 187, in _get_response
    response = self.process_exception_by_middleware(e, request)
  File "/var/www/django/myvenv/lib/python3.4/site-packages/django/core/handlers/base.py", line 185, in _get_response
    response = wrapped_callback(request, *callback_args, **callback_kwargs)
  File "/var/www/django/myvenv/lib/python3.4/site-packages/django/views/decorators/cache.py", line 57, in _wrapped_view_func
    response = view_func(request, *args, **kwargs)
  File "/var/www/django/myvenv/lib/python3.4/site-packages/django/contrib/admin/sites.py", line 393, in login
    return LoginView.as_view(**defaults)(request)
  File "/var/www/django/myvenv/lib/python3.4/site-packages/django/views/generic/base.py", line 68, in view
    return self.dispatch(request, *args, **kwargs)
  File "/var/www/django/myvenv/lib/python3.4/site-packages/django/utils/decorators.py", line 67, in _wrapper
    return bound_func(*args, **kwargs)
  File "/var/www/django/myvenv/lib/python3.4/site-packages/django/views/decorators/debug.py", line 76, in sensitive_post_parameters_wrapper
    return view(request, *args, **kwargs)
  File "/var/www/django/myvenv/lib/python3.4/site-packages/django/utils/decorators.py", line 63, in bound_func
    return func.__get__(self, type(self))(*args2, **kwargs2)
  File "/var/www/django/myvenv/lib/python3.4/site-packages/django/utils/decorators.py", line 67, in _wrapper
    return bound_func(*args, **kwargs)
  File "/var/www/django/myvenv/lib/python3.4/site-packages/django/utils/decorators.py", line 149, in _wrapped_view
    response = view_func(request, *args, **kwargs)
  File "/var/www/django/myvenv/lib/python3.4/site-packages/django/utils/decorators.py", line 63, in bound_func
    return func.__get__(self, type(self))(*args2, **kwargs2)
  File "/var/www/django/myvenv/lib/python3.4/site-packages/django/utils/decorators.py", line 67, in _wrapper
    return bound_func(*args, **kwargs)
  File "/var/www/django/myvenv/lib/python3.4/site-packages/django/views/decorators/cache.py", line 57, in _wrapped_view_func
    response = view_func(request, *args, **kwargs)
  File "/var/www/django/myvenv/lib/python3.4/site-packages/django/utils/decorators.py", line 63, in bound_func
    return func.__get__(self, type(self))(*args2, **kwargs2)
  File "/var/www/django/myvenv/lib/python3.4/site-packages/django/contrib/auth/views.py", line 90, in dispatch
    return super(LoginView, self).dispatch(request, *args, **kwargs)
  File "/var/www/django/myvenv/lib/python3.4/site-packages/django/views/generic/base.py", line 88, in dispatch
    return handler(request, *args, **kwargs)
  File "/var/www/django/myvenv/lib/python3.4/site-packages/django/views/generic/edit.py", line 183, in post
    return self.form_valid(form)
  File "/var/www/django/myvenv/lib/python3.4/site-packages/django/contrib/auth/views.py", line 119, in form_valid
    auth_login(self.request, form.get_user())
  File "/var/www/django/myvenv/lib/python3.4/site-packages/django/contrib/auth/__init__.py", line 139, in login
    request.session.cycle_key()
  File "/var/www/django/myvenv/lib/python3.4/site-packages/django/contrib/sessions/backends/base.py", line 311, in cycle_key
    self.create()
  File "/var/www/django/myvenv/lib/python3.4/site-packages/django/contrib/sessions/backends/db.py", line 54, in create
    self.save(must_create=True)
  File "/var/www/django/myvenv/lib/python3.4/site-packages/django/contrib/sessions/backends/db.py", line 87, in save
    obj.save(force_insert=must_create, force_update=not must_create, using=using)
  File "/var/www/django/myvenv/lib/python3.4/site-packages/django/db/models/base.py", line 808, in save
    force_update=force_update, update_fields=update_fields)
  File "/var/www/django/myvenv/lib/python3.4/site-packages/django/db/models/base.py", line 838, in save_base
    updated = self._save_table(raw, cls, force_insert, force_update, using, update_fields)
  File "/var/www/django/myvenv/lib/python3.4/site-packages/django/db/models/base.py", line 924, in _save_table
    result = self._do_insert(cls._base_manager, using, fields, update_pk, raw)
  File "/var/www/django/myvenv/lib/python3.4/site-packages/django/db/models/base.py", line 963, in _do_insert
    using=using, raw=raw)
  File "/var/www/django/myvenv/lib/python3.4/site-packages/django/db/models/manager.py", line 85, in manager_method
    return getattr(self.get_queryset(), name)(*args, **kwargs)
  File "/var/www/django/myvenv/lib/python3.4/site-packages/django/db/models/query.py", line 1076, in _insert
    return query.get_compiler(using=using).execute_sql(return_id)
  File "/var/www/django/myvenv/lib/python3.4/site-packages/django/db/models/sql/compiler.py", line 1107, in execute_sql
    cursor.execute(sql, params)
  File "/var/www/django/myvenv/lib/python3.4/site-packages/django/db/backends/utils.py", line 80, in execute
    return super(CursorDebugWrapper, self).execute(sql, params)
  File "/var/www/django/myvenv/lib/python3.4/site-packages/django/db/backends/utils.py", line 65, in execute
    return self.cursor.execute(sql, params)
  File "/var/www/django/myvenv/lib/python3.4/site-packages/django/db/utils.py", line 94, in __exit__
    six.reraise(dj_exc_type, dj_exc_value, traceback)
  File "/var/www/django/myvenv/lib/python3.4/site-packages/django/utils/six.py", line 685, in reraise
    raise value.with_traceback(tb)
  File "/var/www/django/myvenv/lib/python3.4/site-packages/django/db/backends/utils.py", line 65, in execute
    return self.cursor.execute(sql, params)
  File "/var/www/django/myvenv/lib/python3.4/site-packages/django/db/backends/sqlite3/base.py", line 328, in execute
    return Database.Cursor.execute(self, query, params)
django.db.utils.OperationalError: attempt to write a readonly database
[09/Oct/2017 09:07:04] "POST /admin/login/?next=/admin/ HTTP/1.1" 500 225329
[09/Oct/2017 09:07:49] "GET /admin/login/?next=/admin/ HTTP/1.1" 200 1654
Internal Server Error: /admin/login/
Traceback (most recent call last):
  File "/var/www/django/myvenv/lib/python3.4/site-packages/django/db/backends/utils.py", line 65, in execute
    return self.cursor.execute(sql, params)
  File "/var/www/django/myvenv/lib/python3.4/site-packages/django/db/backends/sqlite3/base.py", line 328, in execute
    return Database.Cursor.execute(self, query, params)
sqlite3.OperationalError: attempt to write a readonly database

The above exception was the direct cause of the following exception:

Traceback (most recent call last):
  File "/var/www/django/myvenv/lib/python3.4/site-packages/django/core/handlers/exception.py", line 41, in inner
    response = get_response(request)
  File "/var/www/django/myvenv/lib/python3.4/site-packages/django/core/handlers/base.py", line 249, in _legacy_get_response
    response = self._get_response(request)
  File "/var/www/django/myvenv/lib/python3.4/site-packages/django/core/handlers/base.py", line 187, in _get_response
    response = self.process_exception_by_middleware(e, request)
  File "/var/www/django/myvenv/lib/python3.4/site-packages/django/core/handlers/base.py", line 185, in _get_response
    response = wrapped_callback(request, *callback_args, **callback_kwargs)
  File "/var/www/django/myvenv/lib/python3.4/site-packages/django/views/decorators/cache.py", line 57, in _wrapped_view_func
    response = view_func(request, *args, **kwargs)
  File "/var/www/django/myvenv/lib/python3.4/site-packages/django/contrib/admin/sites.py", line 393, in login
    return LoginView.as_view(**defaults)(request)
  File "/var/www/django/myvenv/lib/python3.4/site-packages/django/views/generic/base.py", line 68, in view
    return self.dispatch(request, *args, **kwargs)
  File "/var/www/django/myvenv/lib/python3.4/site-packages/django/utils/decorators.py", line 67, in _wrapper
    return bound_func(*args, **kwargs)
  File "/var/www/django/myvenv/lib/python3.4/site-packages/django/views/decorators/debug.py", line 76, in sensitive_post_parameters_wrapper
    return view(request, *args, **kwargs)
  File "/var/www/django/myvenv/lib/python3.4/site-packages/django/utils/decorators.py", line 63, in bound_func
    return func.__get__(self, type(self))(*args2, **kwargs2)
  File "/var/www/django/myvenv/lib/python3.4/site-packages/django/utils/decorators.py", line 67, in _wrapper
    return bound_func(*args, **kwargs)
  File "/var/www/django/myvenv/lib/python3.4/site-packages/django/utils/decorators.py", line 149, in _wrapped_view
    response = view_func(request, *args, **kwargs)
  File "/var/www/django/myvenv/lib/python3.4/site-packages/django/utils/decorators.py", line 63, in bound_func
    return func.__get__(self, type(self))(*args2, **kwargs2)
  File "/var/www/django/myvenv/lib/python3.4/site-packages/django/utils/decorators.py", line 67, in _wrapper
    return bound_func(*args, **kwargs)
  File "/var/www/django/myvenv/lib/python3.4/site-packages/django/views/decorators/cache.py", line 57, in _wrapped_view_func
    response = view_func(request, *args, **kwargs)
  File "/var/www/django/myvenv/lib/python3.4/site-packages/django/utils/decorators.py", line 63, in bound_func
    return func.__get__(self, type(self))(*args2, **kwargs2)
  File "/var/www/django/myvenv/lib/python3.4/site-packages/django/contrib/auth/views.py", line 90, in dispatch
    return super(LoginView, self).dispatch(request, *args, **kwargs)
  File "/var/www/django/myvenv/lib/python3.4/site-packages/django/views/generic/base.py", line 88, in dispatch
    return handler(request, *args, **kwargs)
  File "/var/www/django/myvenv/lib/python3.4/site-packages/django/views/generic/edit.py", line 183, in post
    return self.form_valid(form)
  File "/var/www/django/myvenv/lib/python3.4/site-packages/django/contrib/auth/views.py", line 119, in form_valid
    auth_login(self.request, form.get_user())
  File "/var/www/django/myvenv/lib/python3.4/site-packages/django/contrib/auth/__init__.py", line 139, in login
    request.session.cycle_key()
  File "/var/www/django/myvenv/lib/python3.4/site-packages/django/contrib/sessions/backends/base.py", line 311, in cycle_key
    self.create()
  File "/var/www/django/myvenv/lib/python3.4/site-packages/django/contrib/sessions/backends/db.py", line 54, in create
    self.save(must_create=True)
  File "/var/www/django/myvenv/lib/python3.4/site-packages/django/contrib/sessions/backends/db.py", line 87, in save
    obj.save(force_insert=must_create, force_update=not must_create, using=using)
  File "/var/www/django/myvenv/lib/python3.4/site-packages/django/db/models/base.py", line 808, in save
    force_update=force_update, update_fields=update_fields)
  File "/var/www/django/myvenv/lib/python3.4/site-packages/django/db/models/base.py", line 838, in save_base
    updated = self._save_table(raw, cls, force_insert, force_update, using, update_fields)
  File "/var/www/django/myvenv/lib/python3.4/site-packages/django/db/models/base.py", line 924, in _save_table
    result = self._do_insert(cls._base_manager, using, fields, update_pk, raw)
  File "/var/www/django/myvenv/lib/python3.4/site-packages/django/db/models/base.py", line 963, in _do_insert
    using=using, raw=raw)
  File "/var/www/django/myvenv/lib/python3.4/site-packages/django/db/models/manager.py", line 85, in manager_method
    return getattr(self.get_queryset(), name)(*args, **kwargs)
  File "/var/www/django/myvenv/lib/python3.4/site-packages/django/db/models/query.py", line 1076, in _insert
    return query.get_compiler(using=using).execute_sql(return_id)
  File "/var/www/django/myvenv/lib/python3.4/site-packages/django/db/models/sql/compiler.py", line 1107, in execute_sql
    cursor.execute(sql, params)
  File "/var/www/django/myvenv/lib/python3.4/site-packages/django/db/backends/utils.py", line 80, in execute
    return super(CursorDebugWrapper, self).execute(sql, params)
  File "/var/www/django/myvenv/lib/python3.4/site-packages/django/db/backends/utils.py", line 65, in execute
    return self.cursor.execute(sql, params)
  File "/var/www/django/myvenv/lib/python3.4/site-packages/django/db/utils.py", line 94, in __exit__
    six.reraise(dj_exc_type, dj_exc_value, traceback)
  File "/var/www/django/myvenv/lib/python3.4/site-packages/django/utils/six.py", line 685, in reraise
    raise value.with_traceback(tb)
  File "/var/www/django/myvenv/lib/python3.4/site-packages/django/db/backends/utils.py", line 65, in execute
    return self.cursor.execute(sql, params)
  File "/var/www/django/myvenv/lib/python3.4/site-packages/django/db/backends/sqlite3/base.py", line 328, in execute
    return Database.Cursor.execute(self, query, params)
django.db.utils.OperationalError: attempt to write a readonly database
[09/Oct/2017 09:07:54] "POST /admin/login/?next=/admin/ HTTP/1.1" 500 225331
[09/Oct/2017 09:07:56] "GET /admin/login/?next=/admin/ HTTP/1.1" 200 1654
[09/Oct/2017 09:08:26] "GET /admin/login/?next=/admin/ HTTP/1.1" 200 1654
[09/Oct/2017 09:08:26] "GET /static/admin/css/login.css HTTP/1.1" 200 1203
[09/Oct/2017 09:08:26] "GET /static/admin/css/base.css HTTP/1.1" 200 16066
[09/Oct/2017 09:08:26] "GET /static/admin/css/fonts.css HTTP/1.1" 200 423
[09/Oct/2017 09:08:26] "GET /static/admin/fonts/Roboto-Regular-webfont.woff HTTP/1.1" 200 80304
[09/Oct/2017 09:08:26] "GET /static/admin/fonts/Roboto-Light-webfont.woff HTTP/1.1" 200 81348
Not Found: /favicon.ico
[09/Oct/2017 09:08:26] "GET /favicon.ico HTTP/1.1" 404 1975
Internal Server Error: /admin/login/
Traceback (most recent call last):
  File "/var/www/django/myvenv/lib/python3.4/site-packages/django/db/backends/utils.py", line 65, in execute
    return self.cursor.execute(sql, params)
  File "/var/www/django/myvenv/lib/python3.4/site-packages/django/db/backends/sqlite3/base.py", line 328, in execute
    return Database.Cursor.execute(self, query, params)
sqlite3.OperationalError: attempt to write a readonly database

The above exception was the direct cause of the following exception:

Traceback (most recent call last):
  File "/var/www/django/myvenv/lib/python3.4/site-packages/django/core/handlers/exception.py", line 41, in inner
    response = get_response(request)
  File "/var/www/django/myvenv/lib/python3.4/site-packages/django/core/handlers/base.py", line 249, in _legacy_get_response
    response = self._get_response(request)
  File "/var/www/django/myvenv/lib/python3.4/site-packages/django/core/handlers/base.py", line 187, in _get_response
    response = self.process_exception_by_middleware(e, request)
  File "/var/www/django/myvenv/lib/python3.4/site-packages/django/core/handlers/base.py", line 185, in _get_response
    response = wrapped_callback(request, *callback_args, **callback_kwargs)
  File "/var/www/django/myvenv/lib/python3.4/site-packages/django/views/decorators/cache.py", line 57, in _wrapped_view_func
    response = view_func(request, *args, **kwargs)
  File "/var/www/django/myvenv/lib/python3.4/site-packages/django/contrib/admin/sites.py", line 393, in login
    return LoginView.as_view(**defaults)(request)
  File "/var/www/django/myvenv/lib/python3.4/site-packages/django/views/generic/base.py", line 68, in view
    return self.dispatch(request, *args, **kwargs)
  File "/var/www/django/myvenv/lib/python3.4/site-packages/django/utils/decorators.py", line 67, in _wrapper
    return bound_func(*args, **kwargs)
  File "/var/www/django/myvenv/lib/python3.4/site-packages/django/views/decorators/debug.py", line 76, in sensitive_post_parameters_wrapper
    return view(request, *args, **kwargs)
  File "/var/www/django/myvenv/lib/python3.4/site-packages/django/utils/decorators.py", line 63, in bound_func
    return func.__get__(self, type(self))(*args2, **kwargs2)
  File "/var/www/django/myvenv/lib/python3.4/site-packages/django/utils/decorators.py", line 67, in _wrapper
    return bound_func(*args, **kwargs)
  File "/var/www/django/myvenv/lib/python3.4/site-packages/django/utils/decorators.py", line 149, in _wrapped_view
    response = view_func(request, *args, **kwargs)
  File "/var/www/django/myvenv/lib/python3.4/site-packages/django/utils/decorators.py", line 63, in bound_func
    return func.__get__(self, type(self))(*args2, **kwargs2)
  File "/var/www/django/myvenv/lib/python3.4/site-packages/django/utils/decorators.py", line 67, in _wrapper
    return bound_func(*args, **kwargs)
  File "/var/www/django/myvenv/lib/python3.4/site-packages/django/views/decorators/cache.py", line 57, in _wrapped_view_func
    response = view_func(request, *args, **kwargs)
  File "/var/www/django/myvenv/lib/python3.4/site-packages/django/utils/decorators.py", line 63, in bound_func
    return func.__get__(self, type(self))(*args2, **kwargs2)
  File "/var/www/django/myvenv/lib/python3.4/site-packages/django/contrib/auth/views.py", line 90, in dispatch
    return super(LoginView, self).dispatch(request, *args, **kwargs)
  File "/var/www/django/myvenv/lib/python3.4/site-packages/django/views/generic/base.py", line 88, in dispatch
    return handler(request, *args, **kwargs)
  File "/var/www/django/myvenv/lib/python3.4/site-packages/django/views/generic/edit.py", line 183, in post
    return self.form_valid(form)
  File "/var/www/django/myvenv/lib/python3.4/site-packages/django/contrib/auth/views.py", line 119, in form_valid
    auth_login(self.request, form.get_user())
  File "/var/www/django/myvenv/lib/python3.4/site-packages/django/contrib/auth/__init__.py", line 139, in login
    request.session.cycle_key()
  File "/var/www/django/myvenv/lib/python3.4/site-packages/django/contrib/sessions/backends/base.py", line 311, in cycle_key
    self.create()
  File "/var/www/django/myvenv/lib/python3.4/site-packages/django/contrib/sessions/backends/db.py", line 54, in create
    self.save(must_create=True)
  File "/var/www/django/myvenv/lib/python3.4/site-packages/django/contrib/sessions/backends/db.py", line 87, in save
    obj.save(force_insert=must_create, force_update=not must_create, using=using)
  File "/var/www/django/myvenv/lib/python3.4/site-packages/django/db/models/base.py", line 808, in save
    force_update=force_update, update_fields=update_fields)
  File "/var/www/django/myvenv/lib/python3.4/site-packages/django/db/models/base.py", line 838, in save_base
    updated = self._save_table(raw, cls, force_insert, force_update, using, update_fields)
  File "/var/www/django/myvenv/lib/python3.4/site-packages/django/db/models/base.py", line 924, in _save_table
    result = self._do_insert(cls._base_manager, using, fields, update_pk, raw)
  File "/var/www/django/myvenv/lib/python3.4/site-packages/django/db/models/base.py", line 963, in _do_insert
    using=using, raw=raw)
  File "/var/www/django/myvenv/lib/python3.4/site-packages/django/db/models/manager.py", line 85, in manager_method
    return getattr(self.get_queryset(), name)(*args, **kwargs)
  File "/var/www/django/myvenv/lib/python3.4/site-packages/django/db/models/query.py", line 1076, in _insert
    return query.get_compiler(using=using).execute_sql(return_id)
  File "/var/www/django/myvenv/lib/python3.4/site-packages/django/db/models/sql/compiler.py", line 1107, in execute_sql
    cursor.execute(sql, params)
  File "/var/www/django/myvenv/lib/python3.4/site-packages/django/db/backends/utils.py", line 80, in execute
    return super(CursorDebugWrapper, self).execute(sql, params)
  File "/var/www/django/myvenv/lib/python3.4/site-packages/django/db/backends/utils.py", line 65, in execute
    return self.cursor.execute(sql, params)
  File "/var/www/django/myvenv/lib/python3.4/site-packages/django/db/utils.py", line 94, in __exit__
    six.reraise(dj_exc_type, dj_exc_value, traceback)
  File "/var/www/django/myvenv/lib/python3.4/site-packages/django/utils/six.py", line 685, in reraise
    raise value.with_traceback(tb)
  File "/var/www/django/myvenv/lib/python3.4/site-packages/django/db/backends/utils.py", line 65, in execute
    return self.cursor.execute(sql, params)
  File "/var/www/django/myvenv/lib/python3.4/site-packages/django/db/backends/sqlite3/base.py", line 328, in execute
    return Database.Cursor.execute(self, query, params)
django.db.utils.OperationalError: attempt to write a readonly database
[09/Oct/2017 09:08:29] "POST /admin/login/?next=/admin/ HTTP/1.1" 500 225327
[09/Oct/2017 09:10:01] "GET /admin/login/?next=/admin/ HTTP/1.1" 200 1654
[09/Oct/2017 09:10:03] "GET /admin/login/?next=/admin/ HTTP/1.1" 200 1654
[09/Oct/2017 09:10:03] "GET /static/admin/css/base.css HTTP/1.1" 200 16066
[09/Oct/2017 09:10:03] "GET /static/admin/css/login.css HTTP/1.1" 200 1203
[09/Oct/2017 09:10:03] "GET /static/admin/css/fonts.css HTTP/1.1" 200 423
[09/Oct/2017 09:10:03] "GET /static/admin/fonts/Roboto-Regular-webfont.woff HTTP/1.1" 200 80304
[09/Oct/2017 09:10:03] "GET /static/admin/fonts/Roboto-Light-webfont.woff HTTP/1.1" 200 81348
Not Found: /favicon.ico
[09/Oct/2017 09:10:04] "GET /favicon.ico HTTP/1.1" 404 1975
Internal Server Error: /admin/login/
Traceback (most recent call last):
  File "/var/www/django/myvenv/lib/python3.4/site-packages/django/db/backends/utils.py", line 65, in execute
    return self.cursor.execute(sql, params)
  File "/var/www/django/myvenv/lib/python3.4/site-packages/django/db/backends/sqlite3/base.py", line 328, in execute
    return Database.Cursor.execute(self, query, params)
sqlite3.OperationalError: attempt to write a readonly database

The above exception was the direct cause of the following exception:

Traceback (most recent call last):
  File "/var/www/django/myvenv/lib/python3.4/site-packages/django/core/handlers/exception.py", line 41, in inner
    response = get_response(request)
  File "/var/www/django/myvenv/lib/python3.4/site-packages/django/core/handlers/base.py", line 249, in _legacy_get_response
    response = self._get_response(request)
  File "/var/www/django/myvenv/lib/python3.4/site-packages/django/core/handlers/base.py", line 187, in _get_response
    response = self.process_exception_by_middleware(e, request)
  File "/var/www/django/myvenv/lib/python3.4/site-packages/django/core/handlers/base.py", line 185, in _get_response
    response = wrapped_callback(request, *callback_args, **callback_kwargs)
  File "/var/www/django/myvenv/lib/python3.4/site-packages/django/views/decorators/cache.py", line 57, in _wrapped_view_func
    response = view_func(request, *args, **kwargs)
  File "/var/www/django/myvenv/lib/python3.4/site-packages/django/contrib/admin/sites.py", line 393, in login
    return LoginView.as_view(**defaults)(request)
  File "/var/www/django/myvenv/lib/python3.4/site-packages/django/views/generic/base.py", line 68, in view
    return self.dispatch(request, *args, **kwargs)
  File "/var/www/django/myvenv/lib/python3.4/site-packages/django/utils/decorators.py", line 67, in _wrapper
    return bound_func(*args, **kwargs)
  File "/var/www/django/myvenv/lib/python3.4/site-packages/django/views/decorators/debug.py", line 76, in sensitive_post_parameters_wrapper
    return view(request, *args, **kwargs)
  File "/var/www/django/myvenv/lib/python3.4/site-packages/django/utils/decorators.py", line 63, in bound_func
    return func.__get__(self, type(self))(*args2, **kwargs2)
  File "/var/www/django/myvenv/lib/python3.4/site-packages/django/utils/decorators.py", line 67, in _wrapper
    return bound_func(*args, **kwargs)
  File "/var/www/django/myvenv/lib/python3.4/site-packages/django/utils/decorators.py", line 149, in _wrapped_view
    response = view_func(request, *args, **kwargs)
  File "/var/www/django/myvenv/lib/python3.4/site-packages/django/utils/decorators.py", line 63, in bound_func
    return func.__get__(self, type(self))(*args2, **kwargs2)
  File "/var/www/django/myvenv/lib/python3.4/site-packages/django/utils/decorators.py", line 67, in _wrapper
    return bound_func(*args, **kwargs)
  File "/var/www/django/myvenv/lib/python3.4/site-packages/django/views/decorators/cache.py", line 57, in _wrapped_view_func
    response = view_func(request, *args, **kwargs)
  File "/var/www/django/myvenv/lib/python3.4/site-packages/django/utils/decorators.py", line 63, in bound_func
    return func.__get__(self, type(self))(*args2, **kwargs2)
  File "/var/www/django/myvenv/lib/python3.4/site-packages/django/contrib/auth/views.py", line 90, in dispatch
    return super(LoginView, self).dispatch(request, *args, **kwargs)
  File "/var/www/django/myvenv/lib/python3.4/site-packages/django/views/generic/base.py", line 88, in dispatch
    return handler(request, *args, **kwargs)
  File "/var/www/django/myvenv/lib/python3.4/site-packages/django/views/generic/edit.py", line 183, in post
    return self.form_valid(form)
  File "/var/www/django/myvenv/lib/python3.4/site-packages/django/contrib/auth/views.py", line 119, in form_valid
    auth_login(self.request, form.get_user())
  File "/var/www/django/myvenv/lib/python3.4/site-packages/django/contrib/auth/__init__.py", line 139, in login
    request.session.cycle_key()
  File "/var/www/django/myvenv/lib/python3.4/site-packages/django/contrib/sessions/backends/base.py", line 311, in cycle_key
    self.create()
  File "/var/www/django/myvenv/lib/python3.4/site-packages/django/contrib/sessions/backends/db.py", line 54, in create
    self.save(must_create=True)
  File "/var/www/django/myvenv/lib/python3.4/site-packages/django/contrib/sessions/backends/db.py", line 87, in save
    obj.save(force_insert=must_create, force_update=not must_create, using=using)
  File "/var/www/django/myvenv/lib/python3.4/site-packages/django/db/models/base.py", line 808, in save
    force_update=force_update, update_fields=update_fields)
  File "/var/www/django/myvenv/lib/python3.4/site-packages/django/db/models/base.py", line 838, in save_base
    updated = self._save_table(raw, cls, force_insert, force_update, using, update_fields)
  File "/var/www/django/myvenv/lib/python3.4/site-packages/django/db/models/base.py", line 924, in _save_table
    result = self._do_insert(cls._base_manager, using, fields, update_pk, raw)
  File "/var/www/django/myvenv/lib/python3.4/site-packages/django/db/models/base.py", line 963, in _do_insert
    using=using, raw=raw)
  File "/var/www/django/myvenv/lib/python3.4/site-packages/django/db/models/manager.py", line 85, in manager_method
    return getattr(self.get_queryset(), name)(*args, **kwargs)
  File "/var/www/django/myvenv/lib/python3.4/site-packages/django/db/models/query.py", line 1076, in _insert
    return query.get_compiler(using=using).execute_sql(return_id)
  File "/var/www/django/myvenv/lib/python3.4/site-packages/django/db/models/sql/compiler.py", line 1107, in execute_sql
    cursor.execute(sql, params)
  File "/var/www/django/myvenv/lib/python3.4/site-packages/django/db/backends/utils.py", line 80, in execute
    return super(CursorDebugWrapper, self).execute(sql, params)
  File "/var/www/django/myvenv/lib/python3.4/site-packages/django/db/backends/utils.py", line 65, in execute
    return self.cursor.execute(sql, params)
  File "/var/www/django/myvenv/lib/python3.4/site-packages/django/db/utils.py", line 94, in __exit__
    six.reraise(dj_exc_type, dj_exc_value, traceback)
  File "/var/www/django/myvenv/lib/python3.4/site-packages/django/utils/six.py", line 685, in reraise
    raise value.with_traceback(tb)
  File "/var/www/django/myvenv/lib/python3.4/site-packages/django/db/backends/utils.py", line 65, in execute
    return self.cursor.execute(sql, params)
  File "/var/www/django/myvenv/lib/python3.4/site-packages/django/db/backends/sqlite3/base.py", line 328, in execute
    return Database.Cursor.execute(self, query, params)
django.db.utils.OperationalError: attempt to write a readonly database
[09/Oct/2017 09:10:07] "POST /admin/login/?next=/admin/ HTTP/1.1" 500 225331
Internal Server Error: /admin/login/
Traceback (most recent call last):
  File "/var/www/django/myvenv/lib/python3.4/site-packages/django/db/backends/utils.py", line 65, in execute
    return self.cursor.execute(sql, params)
  File "/var/www/django/myvenv/lib/python3.4/site-packages/django/db/backends/sqlite3/base.py", line 328, in execute
    return Database.Cursor.execute(self, query, params)
sqlite3.OperationalError: attempt to write a readonly database

The above exception was the direct cause of the following exception:

Traceback (most recent call last):
  File "/var/www/django/myvenv/lib/python3.4/site-packages/django/core/handlers/exception.py", line 41, in inner
    response = get_response(request)
  File "/var/www/django/myvenv/lib/python3.4/site-packages/django/core/handlers/base.py", line 249, in _legacy_get_response
    response = self._get_response(request)
  File "/var/www/django/myvenv/lib/python3.4/site-packages/django/core/handlers/base.py", line 187, in _get_response
    response = self.process_exception_by_middleware(e, request)
  File "/var/www/django/myvenv/lib/python3.4/site-packages/django/core/handlers/base.py", line 185, in _get_response
    response = wrapped_callback(request, *callback_args, **callback_kwargs)
  File "/var/www/django/myvenv/lib/python3.4/site-packages/django/views/decorators/cache.py", line 57, in _wrapped_view_func
    response = view_func(request, *args, **kwargs)
  File "/var/www/django/myvenv/lib/python3.4/site-packages/django/contrib/admin/sites.py", line 393, in login
    return LoginView.as_view(**defaults)(request)
  File "/var/www/django/myvenv/lib/python3.4/site-packages/django/views/generic/base.py", line 68, in view
    return self.dispatch(request, *args, **kwargs)
  File "/var/www/django/myvenv/lib/python3.4/site-packages/django/utils/decorators.py", line 67, in _wrapper
    return bound_func(*args, **kwargs)
  File "/var/www/django/myvenv/lib/python3.4/site-packages/django/views/decorators/debug.py", line 76, in sensitive_post_parameters_wrapper
    return view(request, *args, **kwargs)
  File "/var/www/django/myvenv/lib/python3.4/site-packages/django/utils/decorators.py", line 63, in bound_func
    return func.__get__(self, type(self))(*args2, **kwargs2)
  File "/var/www/django/myvenv/lib/python3.4/site-packages/django/utils/decorators.py", line 67, in _wrapper
    return bound_func(*args, **kwargs)
  File "/var/www/django/myvenv/lib/python3.4/site-packages/django/utils/decorators.py", line 149, in _wrapped_view
    response = view_func(request, *args, **kwargs)
  File "/var/www/django/myvenv/lib/python3.4/site-packages/django/utils/decorators.py", line 63, in bound_func
    return func.__get__(self, type(self))(*args2, **kwargs2)
  File "/var/www/django/myvenv/lib/python3.4/site-packages/django/utils/decorators.py", line 67, in _wrapper
    return bound_func(*args, **kwargs)
  File "/var/www/django/myvenv/lib/python3.4/site-packages/django/views/decorators/cache.py", line 57, in _wrapped_view_func
    response = view_func(request, *args, **kwargs)
  File "/var/www/django/myvenv/lib/python3.4/site-packages/django/utils/decorators.py", line 63, in bound_func
    return func.__get__(self, type(self))(*args2, **kwargs2)
  File "/var/www/django/myvenv/lib/python3.4/site-packages/django/contrib/auth/views.py", line 90, in dispatch
    return super(LoginView, self).dispatch(request, *args, **kwargs)
  File "/var/www/django/myvenv/lib/python3.4/site-packages/django/views/generic/base.py", line 88, in dispatch
    return handler(request, *args, **kwargs)
  File "/var/www/django/myvenv/lib/python3.4/site-packages/django/views/generic/edit.py", line 183, in post
    return self.form_valid(form)
  File "/var/www/django/myvenv/lib/python3.4/site-packages/django/contrib/auth/views.py", line 119, in form_valid
    auth_login(self.request, form.get_user())
  File "/var/www/django/myvenv/lib/python3.4/site-packages/django/contrib/auth/__init__.py", line 139, in login
    request.session.cycle_key()
  File "/var/www/django/myvenv/lib/python3.4/site-packages/django/contrib/sessions/backends/base.py", line 311, in cycle_key
    self.create()
  File "/var/www/django/myvenv/lib/python3.4/site-packages/django/contrib/sessions/backends/db.py", line 54, in create
    self.save(must_create=True)
  File "/var/www/django/myvenv/lib/python3.4/site-packages/django/contrib/sessions/backends/db.py", line 87, in save
    obj.save(force_insert=must_create, force_update=not must_create, using=using)
  File "/var/www/django/myvenv/lib/python3.4/site-packages/django/db/models/base.py", line 808, in save
    force_update=force_update, update_fields=update_fields)
  File "/var/www/django/myvenv/lib/python3.4/site-packages/django/db/models/base.py", line 838, in save_base
    updated = self._save_table(raw, cls, force_insert, force_update, using, update_fields)
  File "/var/www/django/myvenv/lib/python3.4/site-packages/django/db/models/base.py", line 924, in _save_table
    result = self._do_insert(cls._base_manager, using, fields, update_pk, raw)
  File "/var/www/django/myvenv/lib/python3.4/site-packages/django/db/models/base.py", line 963, in _do_insert
    using=using, raw=raw)
  File "/var/www/django/myvenv/lib/python3.4/site-packages/django/db/models/manager.py", line 85, in manager_method
    return getattr(self.get_queryset(), name)(*args, **kwargs)
  File "/var/www/django/myvenv/lib/python3.4/site-packages/django/db/models/query.py", line 1076, in _insert
    return query.get_compiler(using=using).execute_sql(return_id)
  File "/var/www/django/myvenv/lib/python3.4/site-packages/django/db/models/sql/compiler.py", line 1107, in execute_sql
    cursor.execute(sql, params)
  File "/var/www/django/myvenv/lib/python3.4/site-packages/django/db/backends/utils.py", line 80, in execute
    return super(CursorDebugWrapper, self).execute(sql, params)
  File "/var/www/django/myvenv/lib/python3.4/site-packages/django/db/backends/utils.py", line 65, in execute
    return self.cursor.execute(sql, params)
  File "/var/www/django/myvenv/lib/python3.4/site-packages/django/db/utils.py", line 94, in __exit__
    six.reraise(dj_exc_type, dj_exc_value, traceback)
  File "/var/www/django/myvenv/lib/python3.4/site-packages/django/utils/six.py", line 685, in reraise
    raise value.with_traceback(tb)
  File "/var/www/django/myvenv/lib/python3.4/site-packages/django/db/backends/utils.py", line 65, in execute
    return self.cursor.execute(sql, params)
  File "/var/www/django/myvenv/lib/python3.4/site-packages/django/db/backends/sqlite3/base.py", line 328, in execute
    return Database.Cursor.execute(self, query, params)
django.db.utils.OperationalError: attempt to write a readonly database
[09/Oct/2017 09:10:32] "POST /admin/login/?next=/admin/ HTTP/1.1" 500 225457
Not Found: /favicon.ico
[09/Oct/2017 09:10:33] "GET /favicon.ico HTTP/1.1" 404 1975
[09/Oct/2017 09:10:41] "GET /admin/login/?next=/admin/ HTTP/1.1" 200 1654
[18/Oct/2017 12:12:10] "GET / HTTP/1.1" 200 1716
Not Found: /favicon.ico
[18/Oct/2017 12:12:10] "GET /favicon.ico HTTP/1.1" 404 1975
[18/Oct/2017 12:12:14] "GET /admin HTTP/1.1" 301 0
[18/Oct/2017 12:12:14] "GET /admin/ HTTP/1.1" 200 5283
[18/Oct/2017 12:12:14] "GET /static/admin/css/dashboard.css HTTP/1.1" 200 412
[18/Oct/2017 12:12:14] "GET /static/admin/css/base.css HTTP/1.1" 200 16066
[18/Oct/2017 12:12:14] "GET /static/admin/css/fonts.css HTTP/1.1" 200 423
[18/Oct/2017 12:12:15] "GET /static/admin/fonts/Roboto-Light-webfont.woff HTTP/1.1" 200 81348
[18/Oct/2017 12:12:15] "GET /static/admin/fonts/Roboto-Bold-webfont.woff HTTP/1.1" 200 82564
[18/Oct/2017 12:12:15] "GET /static/admin/fonts/Roboto-Regular-webfont.woff HTTP/1.1" 200 80304
[18/Oct/2017 12:12:15] "GET /static/admin/img/icon-addlink.svg HTTP/1.1" 200 331
[18/Oct/2017 12:12:15] "GET /static/admin/img/icon-changelink.svg HTTP/1.1" 200 380
[18/Oct/2017 12:38:07] "GET /admin/blog/post/5/change/ HTTP/1.1" 200 8612
[18/Oct/2017 12:38:07] "GET /static/admin/css/forms.css HTTP/1.1" 200 8173
[18/Oct/2017 12:38:07] "GET /static/admin/js/core.js HTTP/1.1" 200 7976
[18/Oct/2017 12:38:07] "GET /static/admin/js/jquery.init.js HTTP/1.1" 200 363
[18/Oct/2017 12:38:07] "GET /static/admin/js/vendor/jquery/jquery.js HTTP/1.1" 200 258648
[18/Oct/2017 12:38:07] "GET /admin/jsi18n/ HTTP/1.1" 200 3189
[18/Oct/2017 12:38:07] "GET /static/admin/js/admin/RelatedObjectLookups.js HTTP/1.1" 200 6591
[18/Oct/2017 12:38:07] "GET /static/admin/js/actions.js HTTP/1.1" 200 6501
[18/Oct/2017 12:38:07] "GET /static/admin/js/urlify.js HTTP/1.1" 200 8186
[18/Oct/2017 12:38:07] "GET /static/admin/js/prepopulate.js HTTP/1.1" 200 1538
[18/Oct/2017 12:38:07] "GET /static/admin/js/calendar.js HTTP/1.1" 200 7790
[18/Oct/2017 12:38:07] "GET /static/admin/js/vendor/xregexp/xregexp.js HTTP/1.1" 200 128820
[18/Oct/2017 12:38:07] "GET /static/admin/js/admin/DateTimeShortcuts.js HTTP/1.1" 200 20529
[18/Oct/2017 12:38:07] "GET /static/admin/css/widgets.css HTTP/1.1" 200 10340
[18/Oct/2017 12:38:07] "GET /static/admin/js/change_form.js HTTP/1.1" 200 712
[18/Oct/2017 12:38:07] "GET /static/admin/js/prepopulate_init.js HTTP/1.1" 200 495
[18/Oct/2017 12:38:07] "GET /static/admin/img/icon-clock.svg HTTP/1.1" 200 677
[18/Oct/2017 12:38:07] "GET /static/admin/img/icon-calendar.svg HTTP/1.1" 200 1086
[18/Oct/2017 12:38:11] "GET /admin/ HTTP/1.1" 200 5283
[18/Oct/2017 12:38:12] "GET /admin/blog/post/3/change/ HTTP/1.1" 200 8192
[18/Oct/2017 12:38:12] "GET /admin/jsi18n/ HTTP/1.1" 200 3189
[18/Oct/2017 12:38:14] "GET /admin/ HTTP/1.1" 200 5283
Performing system checks...

System check identified no issues (0 silenced).
October 18, 2017 - 08:00:55
Django version 1.11.6, using settings 'mysite.settings'
Starting development server at http://192.168.1.123:8000/
Quit the server with CONTROL-C.
Invalid HTTP_HOST header: '192.168.1.123:8000'. You may need to add '192.168.1.123' to ALLOWED_HOSTS.
[18/Oct/2017 14:51:12] "GET / HTTP/1.1" 400 58528
Invalid HTTP_HOST header: '192.168.1.123:8000'. You may need to add '192.168.1.123' to ALLOWED_HOSTS.
[18/Oct/2017 14:51:13] "GET /favicon.ico HTTP/1.1" 400 58736
[18/Oct/2017 14:51:36] "GET / HTTP/1.1" 200 1716
Not Found: /favicon.ico
[18/Oct/2017 14:51:36] "GET /favicon.ico HTTP/1.1" 404 1975
[18/Oct/2017 14:51:39] "GET /admin/ HTTP/1.1" 200 5283
[20/Oct/2017 09:32:55] "GET /admin/ HTTP/1.1" 200 5283
[20/Oct/2017 14:56:31] "GET /admin/ HTTP/1.1" 200 5283
[27/Oct/2017 13:48:37] "GET /admin/ HTTP/1.1" 302 0
[27/Oct/2017 13:48:40] "GET /admin/login/?next=/admin/ HTTP/1.1" 200 1654
[27/Oct/2017 13:48:41] "GET /static/admin/css/base.css HTTP/1.1" 304 0
[27/Oct/2017 13:48:41] "GET /static/admin/css/login.css HTTP/1.1" 200 1203
[27/Oct/2017 13:48:41] "GET /static/admin/css/fonts.css HTTP/1.1" 304 0
[27/Oct/2017 13:48:42] "GET /static/admin/fonts/Roboto-Regular-webfont.woff HTTP/1.1" 304 0
[27/Oct/2017 13:48:42] "GET /static/admin/fonts/Roboto-Light-webfont.woff HTTP/1.1" 304 0
Not Found: /favicon.ico
[27/Oct/2017 13:48:42] "GET /favicon.ico HTTP/1.1" 404 1975
[27/Oct/2017 13:48:47] "POST /admin/login/?next=/admin/ HTTP/1.1" 302 0
[27/Oct/2017 13:48:47] "GET /admin/ HTTP/1.1" 200 5283
[27/Oct/2017 13:48:47] "GET /static/admin/css/dashboard.css HTTP/1.1" 304 0
[27/Oct/2017 13:48:47] "GET /static/admin/fonts/Roboto-Bold-webfont.woff HTTP/1.1" 304 0
[27/Oct/2017 13:48:47] "GET /static/admin/img/icon-addlink.svg HTTP/1.1" 304 0
[27/Oct/2017 13:48:47] "GET /static/admin/img/icon-changelink.svg HTTP/1.1" 304 0
[27/Oct/2017 13:56:50] "GET /admin/ HTTP/1.1" 200 5283
[27/Oct/2017 13:56:51] "GET /admin/ HTTP/1.1" 200 5283
[27/Oct/2017 13:56:52] "GET /admin/ HTTP/1.1" 200 5283
[27/Oct/2017 13:56:55] "GET / HTTP/1.1" 200 1716
[27/Oct/2017 13:56:56] "GET /admin/ HTTP/1.1" 200 5283
[30/Oct/2017 14:03:06] "GET /admin/ HTTP/1.1" 200 5283
[30/Oct/2017 14:03:06] "GET /static/admin/css/base.css HTTP/1.1" 304 0
[30/Oct/2017 14:03:06] "GET /static/admin/css/dashboard.css HTTP/1.1" 304 0
[30/Oct/2017 14:03:07] "GET /static/admin/css/fonts.css HTTP/1.1" 304 0
[30/Oct/2017 14:03:08] "GET /static/admin/fonts/Roboto-Light-webfont.woff HTTP/1.1" 304 0
[30/Oct/2017 14:03:08] "GET /static/admin/fonts/Roboto-Bold-webfont.woff HTTP/1.1" 304 0
[30/Oct/2017 14:03:08] "GET /static/admin/fonts/Roboto-Regular-webfont.woff HTTP/1.1" 304 0
[30/Oct/2017 14:03:08] "GET /static/admin/img/icon-addlink.svg HTTP/1.1" 304 0
[30/Oct/2017 14:03:09] "GET /static/admin/img/icon-changelink.svg HTTP/1.1" 304 0
Not Found: /favicon.ico
[30/Oct/2017 14:03:09] "GET /favicon.ico HTTP/1.1" 404 1975
[30/Oct/2017 14:05:45] "GET / HTTP/1.1" 200 1716
Performing system checks...

System check identified no issues (0 silenced).
October 18, 2017 - 14:51:03
Django version 1.11.6, using settings 'mysite.settings'
Starting development server at http://192.168.1.123:8000/
Quit the server with CONTROL-C.
[31/Oct/2017 14:48:23] "GET / HTTP/1.1" 200 1716
[01/Nov/2017 12:21:07] "GET / HTTP/1.1" 200 1716
[01/Nov/2017 12:22:03] "GET / HTTP/1.1" 200 1716
[03/Nov/2017 08:39:07] "GET / HTTP/1.1" 200 1716
Performing system checks...

System check identified no issues (0 silenced).
October 31, 2017 - 14:48:21
Django version 1.11.6, using settings 'mysite.settings'
Starting development server at http://192.168.1.123:8000/
Quit the server with CONTROL-C.
[03/Nov/2017 12:17:38] "GET /admin HTTP/1.1" 301 0
[03/Nov/2017 12:17:38] "GET /admin/ HTTP/1.1" 200 5283
[03/Nov/2017 12:17:39] "GET /static/admin/css/base.css HTTP/1.1" 200 16066
[03/Nov/2017 12:17:39] "GET /static/admin/css/dashboard.css HTTP/1.1" 200 412
[03/Nov/2017 12:17:39] "GET /static/admin/css/fonts.css HTTP/1.1" 200 423
[03/Nov/2017 12:17:40] "GET /static/admin/fonts/Roboto-Light-webfont.woff HTTP/1.1" 200 81348
[03/Nov/2017 12:17:40] "GET /static/admin/fonts/Roboto-Bold-webfont.woff HTTP/1.1" 200 82564
[03/Nov/2017 12:17:40] "GET /static/admin/img/icon-addlink.svg HTTP/1.1" 200 331
[03/Nov/2017 12:17:40] "GET /static/admin/fonts/Roboto-Regular-webfont.woff HTTP/1.1" 200 80304
[03/Nov/2017 12:17:40] "GET /static/admin/img/icon-changelink.svg HTTP/1.1" 200 380
Not Found: /favicon.ico
[03/Nov/2017 12:17:40] "GET /favicon.ico HTTP/1.1" 404 1975
[03/Nov/2017 12:19:04] "GET /admin/blog/post/ HTTP/1.1" 200 5468
[03/Nov/2017 12:19:04] "GET /static/admin/css/changelists.css HTTP/1.1" 200 6170
[03/Nov/2017 12:19:04] "GET /static/admin/js/core.js HTTP/1.1" 200 7976
[03/Nov/2017 12:19:04] "GET /admin/jsi18n/ HTTP/1.1" 200 3189
[03/Nov/2017 12:19:04] "GET /static/admin/js/admin/RelatedObjectLookups.js HTTP/1.1" 200 6591
[03/Nov/2017 12:19:04] "GET /static/admin/js/prepopulate.js HTTP/1.1" 200 1538
[03/Nov/2017 12:19:04] "GET /static/admin/js/jquery.init.js HTTP/1.1" 200 363
[03/Nov/2017 12:19:04] "GET /static/admin/js/urlify.js HTTP/1.1" 200 8186
[03/Nov/2017 12:19:04] "GET /static/admin/js/actions.js HTTP/1.1" 200 6501
[03/Nov/2017 12:19:04] "GET /static/admin/js/vendor/jquery/jquery.js HTTP/1.1" 200 258648
[03/Nov/2017 12:19:04] "GET /static/admin/js/vendor/xregexp/xregexp.js HTTP/1.1" 200 128820
[03/Nov/2017 12:19:04] "GET /static/admin/img/tooltag-add.svg HTTP/1.1" 200 331
Performing system checks...

System check identified no issues (0 silenced).
November 03, 2017 - 12:17:36
Django version 1.11.6, using settings 'mysite.settings'
Starting development server at http://192.168.1.123:8000/
Quit the server with CONTROL-C.
Unhandled exception in thread started by <function check_errors.<locals>.wrapper at 0x7f2da4efa6a8>
Traceback (most recent call last):
  File "/var/www/django/myvenv/lib/python3.4/site-packages/django/utils/autoreload.py", line 228, in wrapper
    fn(*args, **kwargs)
  File "/var/www/django/myvenv/lib/python3.4/site-packages/django/core/management/commands/runserver.py", line 125, in inner_run
    self.check(display_num_errors=True)
  File "/var/www/django/myvenv/lib/python3.4/site-packages/django/core/management/base.py", line 359, in check
    include_deployment_checks=include_deployment_checks,
  File "/var/www/django/myvenv/lib/python3.4/site-packages/django/core/management/base.py", line 346, in _run_checks
    return checks.run_checks(**kwargs)
  File "/var/www/django/myvenv/lib/python3.4/site-packages/django/core/checks/registry.py", line 81, in run_checks
    new_errors = check(app_configs=app_configs)
  File "/var/www/django/myvenv/lib/python3.4/site-packages/django/core/checks/urls.py", line 16, in check_url_config
    return check_resolver(resolver)
  File "/var/www/django/myvenv/lib/python3.4/site-packages/django/core/checks/urls.py", line 26, in check_resolver
    return check_method()
  File "/var/www/django/myvenv/lib/python3.4/site-packages/django/urls/resolvers.py", line 254, in check
    for pattern in self.url_patterns:
  File "/var/www/django/myvenv/lib/python3.4/site-packages/django/utils/functional.py", line 35, in __get__
    res = instance.__dict__[self.name] = self.func(instance)
  File "/var/www/django/myvenv/lib/python3.4/site-packages/django/urls/resolvers.py", line 405, in url_patterns
    patterns = getattr(self.urlconf_module, "urlpatterns", self.urlconf_module)
  File "/var/www/django/myvenv/lib/python3.4/site-packages/django/utils/functional.py", line 35, in __get__
    res = instance.__dict__[self.name] = self.func(instance)
  File "/var/www/django/myvenv/lib/python3.4/site-packages/django/urls/resolvers.py", line 398, in urlconf_module
    return import_module(self.urlconf_name)
  File "/usr/lib/python3.4/importlib/__init__.py", line 109, in import_module
    return _bootstrap._gcd_import(name[level:], package, level)
  File "<frozen importlib._bootstrap>", line 2254, in _gcd_import
  File "<frozen importlib._bootstrap>", line 2237, in _find_and_load
  File "<frozen importlib._bootstrap>", line 2226, in _find_and_load_unlocked
  File "<frozen importlib._bootstrap>", line 1200, in _load_unlocked
  File "<frozen importlib._bootstrap>", line 1129, in _exec
  File "<frozen importlib._bootstrap>", line 1471, in exec_module
  File "<frozen importlib._bootstrap>", line 321, in _call_with_frames_removed
  File "/var/www/django/mysite/urls.py", line 10, in <module>
    url(r'', include('blog.urls')),
  File "/var/www/django/myvenv/lib/python3.4/site-packages/django/conf/urls/__init__.py", line 50, in include
    urlconf_module = import_module(urlconf_module)
  File "/usr/lib/python3.4/importlib/__init__.py", line 109, in import_module
    return _bootstrap._gcd_import(name[level:], package, level)
  File "<frozen importlib._bootstrap>", line 2254, in _gcd_import
  File "<frozen importlib._bootstrap>", line 2237, in _find_and_load
  File "<frozen importlib._bootstrap>", line 2226, in _find_and_load_unlocked
  File "<frozen importlib._bootstrap>", line 1200, in _load_unlocked
  File "<frozen importlib._bootstrap>", line 1129, in _exec
  File "<frozen importlib._bootstrap>", line 1471, in exec_module
  File "<frozen importlib._bootstrap>", line 321, in _call_with_frames_removed
  File "/var/www/django/blog/urls.py", line 4, in <module>
    url(r'^$', views.post_list, name='post_list'),
AttributeError: 'module' object has no attribute 'post_list'
Performing system checks...

[04/Nov/2017 11:28:52] "GET /admin/ HTTP/1.1" 200 5283
Not Found: /favicon.ico
[04/Nov/2017 11:28:53] "GET /favicon.ico HTTP/1.1" 404 2142
Internal Server Error: /
Traceback (most recent call last):
  File "/var/www/django/myvenv/lib/python3.4/site-packages/django/core/handlers/exception.py", line 41, in inner
    response = get_response(request)
  File "/var/www/django/myvenv/lib/python3.4/site-packages/django/core/handlers/base.py", line 249, in _legacy_get_response
    response = self._get_response(request)
  File "/var/www/django/myvenv/lib/python3.4/site-packages/django/core/handlers/base.py", line 187, in _get_response
    response = self.process_exception_by_middleware(e, request)
  File "/var/www/django/myvenv/lib/python3.4/site-packages/django/core/handlers/base.py", line 185, in _get_response
    response = wrapped_callback(request, *callback_args, **callback_kwargs)
  File "/var/www/django/blog/views.py", line 5, in post_list
    return render(request, 'blog/post_list.html', {})
  File "/var/www/django/myvenv/lib/python3.4/site-packages/django/shortcuts.py", line 30, in render
    content = loader.render_to_string(template_name, context, request, using=using)
  File "/var/www/django/myvenv/lib/python3.4/site-packages/django/template/loader.py", line 67, in render_to_string
    template = get_template(template_name, using=using)
  File "/var/www/django/myvenv/lib/python3.4/site-packages/django/template/loader.py", line 25, in get_template
    raise TemplateDoesNotExist(template_name, chain=chain)
django.template.exceptions.TemplateDoesNotExist: blog/post_list.html
[04/Nov/2017 11:28:56] "GET / HTTP/1.1" 500 77091
Internal Server Error: /
Traceback (most recent call last):
  File "/var/www/django/myvenv/lib/python3.4/site-packages/django/core/handlers/exception.py", line 41, in inner
    response = get_response(request)
  File "/var/www/django/myvenv/lib/python3.4/site-packages/django/core/handlers/base.py", line 249, in _legacy_get_response
    response = self._get_response(request)
  File "/var/www/django/myvenv/lib/python3.4/site-packages/django/core/handlers/base.py", line 187, in _get_response
    response = self.process_exception_by_middleware(e, request)
  File "/var/www/django/myvenv/lib/python3.4/site-packages/django/core/handlers/base.py", line 185, in _get_response
    response = wrapped_callback(request, *callback_args, **callback_kwargs)
  File "/var/www/django/blog/views.py", line 5, in post_list
    return render(request, 'blog/post_list.html', {})
  File "/var/www/django/myvenv/lib/python3.4/site-packages/django/shortcuts.py", line 30, in render
    content = loader.render_to_string(template_name, context, request, using=using)
  File "/var/www/django/myvenv/lib/python3.4/site-packages/django/template/loader.py", line 67, in render_to_string
    template = get_template(template_name, using=using)
  File "/var/www/django/myvenv/lib/python3.4/site-packages/django/template/loader.py", line 25, in get_template
    raise TemplateDoesNotExist(template_name, chain=chain)
django.template.exceptions.TemplateDoesNotExist: blog/post_list.html
[04/Nov/2017 11:33:36] "GET / HTTP/1.1" 500 77226
Internal Server Error: /
Traceback (most recent call last):
  File "/var/www/django/myvenv/lib/python3.4/site-packages/django/core/handlers/exception.py", line 41, in inner
    response = get_response(request)
  File "/var/www/django/myvenv/lib/python3.4/site-packages/django/core/handlers/base.py", line 249, in _legacy_get_response
    response = self._get_response(request)
  File "/var/www/django/myvenv/lib/python3.4/site-packages/django/core/handlers/base.py", line 187, in _get_response
    response = self.process_exception_by_middleware(e, request)
  File "/var/www/django/myvenv/lib/python3.4/site-packages/django/core/handlers/base.py", line 185, in _get_response
    response = wrapped_callback(request, *callback_args, **callback_kwargs)
  File "/var/www/django/blog/views.py", line 5, in post_list
    return render(request, 'blog/post_list.html', {})
  File "/var/www/django/myvenv/lib/python3.4/site-packages/django/shortcuts.py", line 30, in render
    content = loader.render_to_string(template_name, context, request, using=using)
  File "/var/www/django/myvenv/lib/python3.4/site-packages/django/template/loader.py", line 67, in render_to_string
    template = get_template(template_name, using=using)
  File "/var/www/django/myvenv/lib/python3.4/site-packages/django/template/loader.py", line 25, in get_template
    raise TemplateDoesNotExist(template_name, chain=chain)
django.template.exceptions.TemplateDoesNotExist: blog/post_list.html
[04/Nov/2017 11:33:38] "GET / HTTP/1.1" 500 77226
[06/Nov/2017 13:24:50] "GET / HTTP/1.1" 200 0
Not Found: /favicon.ico
[06/Nov/2017 13:24:50] "GET /favicon.ico HTTP/1.1" 404 2142
[06/Nov/2017 13:24:56] "GET / HTTP/1.1" 200 0
[06/Nov/2017 13:24:56] "GET / HTTP/1.1" 200 0
[06/Nov/2017 13:24:57] "GET / HTTP/1.1" 200 0
[06/Nov/2017 13:24:57] "GET / HTTP/1.1" 200 0
[06/Nov/2017 13:24:57] "GET / HTTP/1.1" 200 0
[06/Nov/2017 13:24:58] "GET / HTTP/1.1" 200 0
Not Found: /favicon.ico
[06/Nov/2017 13:24:58] "GET /favicon.ico HTTP/1.1" 404 2142
[06/Nov/2017 13:25:02] "GET / HTTP/1.1" 200 0
[06/Nov/2017 13:25:07] "GET /admin HTTP/1.1" 301 0
[06/Nov/2017 13:25:07] "GET /admin/ HTTP/1.1" 302 0
[06/Nov/2017 13:25:07] "GET /admin/login/?next=/admin/ HTTP/1.1" 200 1654
[06/Nov/2017 13:25:07] "GET /static/admin/css/login.css HTTP/1.1" 200 1203
[06/Nov/2017 13:25:07] "GET /static/admin/css/base.css HTTP/1.1" 200 16066
[06/Nov/2017 13:25:08] "GET /static/admin/css/fonts.css HTTP/1.1" 200 423
[06/Nov/2017 13:25:08] "GET /static/admin/fonts/Roboto-Regular-webfont.woff HTTP/1.1" 200 80304
[06/Nov/2017 13:25:08] "GET /static/admin/fonts/Roboto-Light-webfont.woff HTTP/1.1" 200 81348
[06/Nov/2017 13:25:17] "GET / HTTP/1.1" 200 0
[06/Nov/2017 13:25:32] "GET / HTTP/1.1" 200 0
[06/Nov/2017 13:26:04] "GET / HTTP/1.1" 200 11
[07/Nov/2017 07:40:30] "GET / HTTP/1.1" 200 56
[07/Nov/2017 14:15:35] "GET / HTTP/1.1" 200 56
[07/Nov/2017 14:24:17] "GET / HTTP/1.1" 200 144
[07/Nov/2017 14:25:17] "GET / HTTP/1.1" 200 931
[07/Nov/2017 14:25:32] "GET / HTTP/1.1" 200 931
[07/Nov/2017 14:25:33] "GET / HTTP/1.1" 200 931
[07/Nov/2017 14:25:35] "GET / HTTP/1.1" 200 931
[08/Nov/2017 07:41:31] "GET / HTTP/1.1" 200 931
[09/Nov/2017 13:54:56] "GET / HTTP/1.1" 200 931
[09/Nov/2017 13:55:04] "GET /admin/ HTTP/1.1" 200 5283
[09/Nov/2017 13:55:04] "GET /static/admin/css/base.css HTTP/1.1" 304 0
[09/Nov/2017 13:55:04] "GET /static/admin/css/dashboard.css HTTP/1.1" 304 0
[09/Nov/2017 13:55:05] "GET /static/admin/css/fonts.css HTTP/1.1" 304 0
[09/Nov/2017 13:55:05] "GET /static/admin/img/icon-addlink.svg HTTP/1.1" 304 0
[09/Nov/2017 13:55:05] "GET /static/admin/fonts/Roboto-Regular-webfont.woff HTTP/1.1" 304 0
[09/Nov/2017 13:55:05] "GET /static/admin/fonts/Roboto-Bold-webfont.woff HTTP/1.1" 304 0
[09/Nov/2017 13:55:05] "GET /static/admin/fonts/Roboto-Light-webfont.woff HTTP/1.1" 304 0
[09/Nov/2017 13:55:05] "GET /static/admin/img/icon-changelink.svg HTTP/1.1" 304 0
[09/Nov/2017 13:55:10] "GET /admin/blog/post/ HTTP/1.1" 200 5691
[09/Nov/2017 13:55:10] "GET /static/admin/css/changelists.css HTTP/1.1" 200 6170
[09/Nov/2017 13:55:10] "GET /static/admin/js/core.js HTTP/1.1" 304 0
[09/Nov/2017 13:55:10] "GET /admin/jsi18n/ HTTP/1.1" 200 3189
[09/Nov/2017 13:55:10] "GET /static/admin/js/jquery.init.js HTTP/1.1" 200 363
[09/Nov/2017 13:55:10] "GET /static/admin/js/vendor/jquery/jquery.js HTTP/1.1" 304 0
[09/Nov/2017 13:55:10] "GET /static/admin/js/admin/RelatedObjectLookups.js HTTP/1.1" 304 0
[09/Nov/2017 13:55:10] "GET /static/admin/js/actions.js HTTP/1.1" 304 0
[09/Nov/2017 13:55:10] "GET /static/admin/js/prepopulate.js HTTP/1.1" 304 0
[09/Nov/2017 13:55:10] "GET /static/admin/js/urlify.js HTTP/1.1" 304 0
[09/Nov/2017 13:55:10] "GET /static/admin/js/vendor/xregexp/xregexp.js HTTP/1.1" 304 0
[09/Nov/2017 13:55:11] "GET /static/admin/img/tooltag-add.svg HTTP/1.1" 200 331
[09/Nov/2017 13:55:18] "GET /admin/ HTTP/1.1" 200 5283
[09/Nov/2017 13:55:26] "GET / HTTP/1.1" 200 931
[09/Nov/2017 13:55:28] "GET /admin/ HTTP/1.1" 200 5283
[09/Nov/2017 13:55:35] "GET /admin/ HTTP/1.1" 200 5283
Performing system checks...

System check identified no issues (0 silenced).
November 04, 2017 - 12:37:17
Django version 1.11.6, using settings 'mysite.settings'
Starting development server at http://192.168.1.123:8000/
Quit the server with CONTROL-C.
Performing system checks...

System check identified no issues (0 silenced).
November 09, 2017 - 13:59:14
Django version 1.11.6, using settings 'mysite.settings'
Starting development server at http://192.168.1.123:8000/
Quit the server with CONTROL-C.
Performing system checks...

System check identified no issues (0 silenced).
November 09, 2017 - 14:00:48
Django version 1.11.6, using settings 'mysite.settings'
Starting development server at http://192.168.1.123:8000/
Quit the server with CONTROL-C.
Unhandled exception in thread started by <function check_errors.<locals>.wrapper at 0x7f19e42f66a8>
Traceback (most recent call last):
  File "/var/www/django/myvenv/lib/python3.4/site-packages/django/utils/autoreload.py", line 228, in wrapper
    fn(*args, **kwargs)
  File "/var/www/django/myvenv/lib/python3.4/site-packages/django/core/management/commands/runserver.py", line 125, in inner_run
    self.check(display_num_errors=True)
  File "/var/www/django/myvenv/lib/python3.4/site-packages/django/core/management/base.py", line 359, in check
    include_deployment_checks=include_deployment_checks,
  File "/var/www/django/myvenv/lib/python3.4/site-packages/django/core/management/base.py", line 346, in _run_checks
    return checks.run_checks(**kwargs)
  File "/var/www/django/myvenv/lib/python3.4/site-packages/django/core/checks/registry.py", line 81, in run_checks
    new_errors = check(app_configs=app_configs)
  File "/var/www/django/myvenv/lib/python3.4/site-packages/django/core/checks/urls.py", line 16, in check_url_config
    return check_resolver(resolver)
  File "/var/www/django/myvenv/lib/python3.4/site-packages/django/core/checks/urls.py", line 26, in check_resolver
    return check_method()
  File "/var/www/django/myvenv/lib/python3.4/site-packages/django/urls/resolvers.py", line 254, in check
    for pattern in self.url_patterns:
  File "/var/www/django/myvenv/lib/python3.4/site-packages/django/utils/functional.py", line 35, in __get__
    res = instance.__dict__[self.name] = self.func(instance)
  File "/var/www/django/myvenv/lib/python3.4/site-packages/django/urls/resolvers.py", line 405, in url_patterns
    patterns = getattr(self.urlconf_module, "urlpatterns", self.urlconf_module)
  File "/var/www/django/myvenv/lib/python3.4/site-packages/django/utils/functional.py", line 35, in __get__
    res = instance.__dict__[self.name] = self.func(instance)
  File "/var/www/django/myvenv/lib/python3.4/site-packages/django/urls/resolvers.py", line 398, in urlconf_module
    return import_module(self.urlconf_name)
  File "/usr/lib/python3.4/importlib/__init__.py", line 109, in import_module
    return _bootstrap._gcd_import(name[level:], package, level)
  File "<frozen importlib._bootstrap>", line 2254, in _gcd_import
  File "<frozen importlib._bootstrap>", line 2237, in _find_and_load
  File "<frozen importlib._bootstrap>", line 2226, in _find_and_load_unlocked
  File "<frozen importlib._bootstrap>", line 1200, in _load_unlocked
  File "<frozen importlib._bootstrap>", line 1129, in _exec
  File "<frozen importlib._bootstrap>", line 1471, in exec_module
  File "<frozen importlib._bootstrap>", line 321, in _call_with_frames_removed
  File "/var/www/django/mysite/urls.py", line 10, in <module>
    url(r'', include('blog.urls')),
  File "/var/www/django/myvenv/lib/python3.4/site-packages/django/conf/urls/__init__.py", line 50, in include
    urlconf_module = import_module(urlconf_module)
  File "/usr/lib/python3.4/importlib/__init__.py", line 109, in import_module
    return _bootstrap._gcd_import(name[level:], package, level)
  File "<frozen importlib._bootstrap>", line 2254, in _gcd_import
  File "<frozen importlib._bootstrap>", line 2237, in _find_and_load
  File "<frozen importlib._bootstrap>", line 2226, in _find_and_load_unlocked
  File "<frozen importlib._bootstrap>", line 1200, in _load_unlocked
  File "<frozen importlib._bootstrap>", line 1129, in _exec
  File "<frozen importlib._bootstrap>", line 1471, in exec_module
  File "<frozen importlib._bootstrap>", line 321, in _call_with_frames_removed
  File "/var/www/django/blog/urls.py", line 2, in <module>
    from . import views
  File "/var/www/django/blog/views.py", line 8
    Post.objects.filter(published_date__lte=timezone.now()).order_by('published_date')
       ^
IndentationError: expected an indented block
Performing system checks...

Unhandled exception in thread started by <function check_errors.<locals>.wrapper at 0x7ff8d696e6a8>
Traceback (most recent call last):
  File "/var/www/django/myvenv/lib/python3.4/site-packages/django/utils/autoreload.py", line 228, in wrapper
    fn(*args, **kwargs)
  File "/var/www/django/myvenv/lib/python3.4/site-packages/django/core/management/commands/runserver.py", line 125, in inner_run
    self.check(display_num_errors=True)
  File "/var/www/django/myvenv/lib/python3.4/site-packages/django/core/management/base.py", line 359, in check
    include_deployment_checks=include_deployment_checks,
  File "/var/www/django/myvenv/lib/python3.4/site-packages/django/core/management/base.py", line 346, in _run_checks
    return checks.run_checks(**kwargs)
  File "/var/www/django/myvenv/lib/python3.4/site-packages/django/core/checks/registry.py", line 81, in run_checks
    new_errors = check(app_configs=app_configs)
  File "/var/www/django/myvenv/lib/python3.4/site-packages/django/core/checks/urls.py", line 16, in check_url_config
    return check_resolver(resolver)
  File "/var/www/django/myvenv/lib/python3.4/site-packages/django/core/checks/urls.py", line 26, in check_resolver
    return check_method()
  File "/var/www/django/myvenv/lib/python3.4/site-packages/django/urls/resolvers.py", line 254, in check
    for pattern in self.url_patterns:
  File "/var/www/django/myvenv/lib/python3.4/site-packages/django/utils/functional.py", line 35, in __get__
    res = instance.__dict__[self.name] = self.func(instance)
  File "/var/www/django/myvenv/lib/python3.4/site-packages/django/urls/resolvers.py", line 405, in url_patterns
    patterns = getattr(self.urlconf_module, "urlpatterns", self.urlconf_module)
  File "/var/www/django/myvenv/lib/python3.4/site-packages/django/utils/functional.py", line 35, in __get__
    res = instance.__dict__[self.name] = self.func(instance)
  File "/var/www/django/myvenv/lib/python3.4/site-packages/django/urls/resolvers.py", line 398, in urlconf_module
    return import_module(self.urlconf_name)
  File "/usr/lib/python3.4/importlib/__init__.py", line 109, in import_module
    return _bootstrap._gcd_import(name[level:], package, level)
  File "<frozen importlib._bootstrap>", line 2254, in _gcd_import
  File "<frozen importlib._bootstrap>", line 2237, in _find_and_load
  File "<frozen importlib._bootstrap>", line 2226, in _find_and_load_unlocked
  File "<frozen importlib._bootstrap>", line 1200, in _load_unlocked
  File "<frozen importlib._bootstrap>", line 1129, in _exec
  File "<frozen importlib._bootstrap>", line 1471, in exec_module
  File "<frozen importlib._bootstrap>", line 321, in _call_with_frames_removed
  File "/var/www/django/mysite/urls.py", line 10, in <module>
    url(r'', include('blog.urls')),
  File "/var/www/django/myvenv/lib/python3.4/site-packages/django/conf/urls/__init__.py", line 50, in include
    urlconf_module = import_module(urlconf_module)
  File "/usr/lib/python3.4/importlib/__init__.py", line 109, in import_module
    return _bootstrap._gcd_import(name[level:], package, level)
  File "<frozen importlib._bootstrap>", line 2254, in _gcd_import
  File "<frozen importlib._bootstrap>", line 2237, in _find_and_load
  File "<frozen importlib._bootstrap>", line 2226, in _find_and_load_unlocked
  File "<frozen importlib._bootstrap>", line 1200, in _load_unlocked
  File "<frozen importlib._bootstrap>", line 1129, in _exec
  File "<frozen importlib._bootstrap>", line 1471, in exec_module
  File "<frozen importlib._bootstrap>", line 321, in _call_with_frames_removed
  File "/var/www/django/blog/urls.py", line 2, in <module>
    from . import views
  File "/var/www/django/blog/views.py", line 8
    Post.objects.filter(published_date__lte=timezone.now()).order_by('published_date')
       ^
IndentationError: expected an indented block
Performing system checks...

Unhandled exception in thread started by <function check_errors.<locals>.wrapper at 0x7fe52c5c96a8>
Traceback (most recent call last):
  File "/var/www/django/myvenv/lib/python3.4/site-packages/django/utils/autoreload.py", line 228, in wrapper
    fn(*args, **kwargs)
  File "/var/www/django/myvenv/lib/python3.4/site-packages/django/core/management/commands/runserver.py", line 125, in inner_run
    self.check(display_num_errors=True)
  File "/var/www/django/myvenv/lib/python3.4/site-packages/django/core/management/base.py", line 359, in check
    include_deployment_checks=include_deployment_checks,
  File "/var/www/django/myvenv/lib/python3.4/site-packages/django/core/management/base.py", line 346, in _run_checks
    return checks.run_checks(**kwargs)
  File "/var/www/django/myvenv/lib/python3.4/site-packages/django/core/checks/registry.py", line 81, in run_checks
    new_errors = check(app_configs=app_configs)
  File "/var/www/django/myvenv/lib/python3.4/site-packages/django/core/checks/urls.py", line 16, in check_url_config
    return check_resolver(resolver)
  File "/var/www/django/myvenv/lib/python3.4/site-packages/django/core/checks/urls.py", line 26, in check_resolver
    return check_method()
  File "/var/www/django/myvenv/lib/python3.4/site-packages/django/urls/resolvers.py", line 254, in check
    for pattern in self.url_patterns:
  File "/var/www/django/myvenv/lib/python3.4/site-packages/django/utils/functional.py", line 35, in __get__
    res = instance.__dict__[self.name] = self.func(instance)
  File "/var/www/django/myvenv/lib/python3.4/site-packages/django/urls/resolvers.py", line 405, in url_patterns
    patterns = getattr(self.urlconf_module, "urlpatterns", self.urlconf_module)
  File "/var/www/django/myvenv/lib/python3.4/site-packages/django/utils/functional.py", line 35, in __get__
    res = instance.__dict__[self.name] = self.func(instance)
  File "/var/www/django/myvenv/lib/python3.4/site-packages/django/urls/resolvers.py", line 398, in urlconf_module
    return import_module(self.urlconf_name)
  File "/usr/lib/python3.4/importlib/__init__.py", line 109, in import_module
    return _bootstrap._gcd_import(name[level:], package, level)
  File "<frozen importlib._bootstrap>", line 2254, in _gcd_import
  File "<frozen importlib._bootstrap>", line 2237, in _find_and_load
  File "<frozen importlib._bootstrap>", line 2226, in _find_and_load_unlocked
  File "<frozen importlib._bootstrap>", line 1200, in _load_unlocked
  File "<frozen importlib._bootstrap>", line 1129, in _exec
  File "<frozen importlib._bootstrap>", line 1471, in exec_module
  File "<frozen importlib._bootstrap>", line 321, in _call_with_frames_removed
  File "/var/www/django/mysite/urls.py", line 10, in <module>
    url(r'', include('blog.urls')),
  File "/var/www/django/myvenv/lib/python3.4/site-packages/django/conf/urls/__init__.py", line 50, in include
    urlconf_module = import_module(urlconf_module)
  File "/usr/lib/python3.4/importlib/__init__.py", line 109, in import_module
    return _bootstrap._gcd_import(name[level:], package, level)
  File "<frozen importlib._bootstrap>", line 2254, in _gcd_import
  File "<frozen importlib._bootstrap>", line 2237, in _find_and_load
  File "<frozen importlib._bootstrap>", line 2226, in _find_and_load_unlocked
  File "<frozen importlib._bootstrap>", line 1200, in _load_unlocked
  File "<frozen importlib._bootstrap>", line 1129, in _exec
  File "<frozen importlib._bootstrap>", line 1471, in exec_module
  File "<frozen importlib._bootstrap>", line 321, in _call_with_frames_removed
  File "/var/www/django/blog/urls.py", line 2, in <module>
    from . import views
  File "/var/www/django/blog/views.py", line 8
    Post.objects.filter(published_date__lte=timezone.now()).order_by('published_date')
       ^
IndentationError: expected an indented block
Performing system checks...

Unhandled exception in thread started by <function check_errors.<locals>.wrapper at 0x7f411694f6a8>
Traceback (most recent call last):
  File "/var/www/django/myvenv/lib/python3.4/site-packages/django/utils/autoreload.py", line 228, in wrapper
    fn(*args, **kwargs)
  File "/var/www/django/myvenv/lib/python3.4/site-packages/django/core/management/commands/runserver.py", line 125, in inner_run
    self.check(display_num_errors=True)
  File "/var/www/django/myvenv/lib/python3.4/site-packages/django/core/management/base.py", line 359, in check
    include_deployment_checks=include_deployment_checks,
  File "/var/www/django/myvenv/lib/python3.4/site-packages/django/core/management/base.py", line 346, in _run_checks
    return checks.run_checks(**kwargs)
  File "/var/www/django/myvenv/lib/python3.4/site-packages/django/core/checks/registry.py", line 81, in run_checks
    new_errors = check(app_configs=app_configs)
  File "/var/www/django/myvenv/lib/python3.4/site-packages/django/core/checks/urls.py", line 16, in check_url_config
    return check_resolver(resolver)
  File "/var/www/django/myvenv/lib/python3.4/site-packages/django/core/checks/urls.py", line 26, in check_resolver
    return check_method()
  File "/var/www/django/myvenv/lib/python3.4/site-packages/django/urls/resolvers.py", line 254, in check
    for pattern in self.url_patterns:
  File "/var/www/django/myvenv/lib/python3.4/site-packages/django/utils/functional.py", line 35, in __get__
    res = instance.__dict__[self.name] = self.func(instance)
  File "/var/www/django/myvenv/lib/python3.4/site-packages/django/urls/resolvers.py", line 405, in url_patterns
    patterns = getattr(self.urlconf_module, "urlpatterns", self.urlconf_module)
  File "/var/www/django/myvenv/lib/python3.4/site-packages/django/utils/functional.py", line 35, in __get__
    res = instance.__dict__[self.name] = self.func(instance)
  File "/var/www/django/myvenv/lib/python3.4/site-packages/django/urls/resolvers.py", line 398, in urlconf_module
    return import_module(self.urlconf_name)
  File "/usr/lib/python3.4/importlib/__init__.py", line 109, in import_module
    return _bootstrap._gcd_import(name[level:], package, level)
  File "<frozen importlib._bootstrap>", line 2254, in _gcd_import
  File "<frozen importlib._bootstrap>", line 2237, in _find_and_load
  File "<frozen importlib._bootstrap>", line 2226, in _find_and_load_unlocked
  File "<frozen importlib._bootstrap>", line 1200, in _load_unlocked
  File "<frozen importlib._bootstrap>", line 1129, in _exec
  File "<frozen importlib._bootstrap>", line 1471, in exec_module
  File "<frozen importlib._bootstrap>", line 321, in _call_with_frames_removed
  File "/var/www/django/mysite/urls.py", line 10, in <module>
    url(r'', include('blog.urls')),
  File "/var/www/django/myvenv/lib/python3.4/site-packages/django/conf/urls/__init__.py", line 50, in include
    urlconf_module = import_module(urlconf_module)
  File "/usr/lib/python3.4/importlib/__init__.py", line 109, in import_module
    return _bootstrap._gcd_import(name[level:], package, level)
  File "<frozen importlib._bootstrap>", line 2254, in _gcd_import
  File "<frozen importlib._bootstrap>", line 2237, in _find_and_load
  File "<frozen importlib._bootstrap>", line 2226, in _find_and_load_unlocked
  File "<frozen importlib._bootstrap>", line 1200, in _load_unlocked
  File "<frozen importlib._bootstrap>", line 1129, in _exec
  File "<frozen importlib._bootstrap>", line 1471, in exec_module
  File "<frozen importlib._bootstrap>", line 321, in _call_with_frames_removed
  File "/var/www/django/blog/urls.py", line 2, in <module>
    from . import views
  File "/var/www/django/blog/views.py", line 8
    Post.objects.filter(published_date__lte=timezone.now()).order_by('published_date')
       ^
IndentationError: expected an indented block
Performing system checks...

Unhandled exception in thread started by <function check_errors.<locals>.wrapper at 0x7f648cb8e6a8>
Traceback (most recent call last):
  File "/var/www/django/myvenv/lib/python3.4/site-packages/django/utils/autoreload.py", line 228, in wrapper
    fn(*args, **kwargs)
  File "/var/www/django/myvenv/lib/python3.4/site-packages/django/core/management/commands/runserver.py", line 125, in inner_run
    self.check(display_num_errors=True)
  File "/var/www/django/myvenv/lib/python3.4/site-packages/django/core/management/base.py", line 359, in check
    include_deployment_checks=include_deployment_checks,
  File "/var/www/django/myvenv/lib/python3.4/site-packages/django/core/management/base.py", line 346, in _run_checks
    return checks.run_checks(**kwargs)
  File "/var/www/django/myvenv/lib/python3.4/site-packages/django/core/checks/registry.py", line 81, in run_checks
    new_errors = check(app_configs=app_configs)
  File "/var/www/django/myvenv/lib/python3.4/site-packages/django/core/checks/urls.py", line 16, in check_url_config
    return check_resolver(resolver)
  File "/var/www/django/myvenv/lib/python3.4/site-packages/django/core/checks/urls.py", line 26, in check_resolver
    return check_method()
  File "/var/www/django/myvenv/lib/python3.4/site-packages/django/urls/resolvers.py", line 254, in check
    for pattern in self.url_patterns:
  File "/var/www/django/myvenv/lib/python3.4/site-packages/django/utils/functional.py", line 35, in __get__
    res = instance.__dict__[self.name] = self.func(instance)
  File "/var/www/django/myvenv/lib/python3.4/site-packages/django/urls/resolvers.py", line 405, in url_patterns
    patterns = getattr(self.urlconf_module, "urlpatterns", self.urlconf_module)
  File "/var/www/django/myvenv/lib/python3.4/site-packages/django/utils/functional.py", line 35, in __get__
    res = instance.__dict__[self.name] = self.func(instance)
  File "/var/www/django/myvenv/lib/python3.4/site-packages/django/urls/resolvers.py", line 398, in urlconf_module
    return import_module(self.urlconf_name)
  File "/usr/lib/python3.4/importlib/__init__.py", line 109, in import_module
    return _bootstrap._gcd_import(name[level:], package, level)
  File "<frozen importlib._bootstrap>", line 2254, in _gcd_import
  File "<frozen importlib._bootstrap>", line 2237, in _find_and_load
  File "<frozen importlib._bootstrap>", line 2226, in _find_and_load_unlocked
  File "<frozen importlib._bootstrap>", line 1200, in _load_unlocked
  File "<frozen importlib._bootstrap>", line 1129, in _exec
  File "<frozen importlib._bootstrap>", line 1471, in exec_module
  File "<frozen importlib._bootstrap>", line 321, in _call_with_frames_removed
  File "/var/www/django/mysite/urls.py", line 10, in <module>
    url(r'', include('blog.urls')),
  File "/var/www/django/myvenv/lib/python3.4/site-packages/django/conf/urls/__init__.py", line 50, in include
    urlconf_module = import_module(urlconf_module)
  File "/usr/lib/python3.4/importlib/__init__.py", line 109, in import_module
    return _bootstrap._gcd_import(name[level:], package, level)
  File "<frozen importlib._bootstrap>", line 2254, in _gcd_import
  File "<frozen importlib._bootstrap>", line 2237, in _find_and_load
  File "<frozen importlib._bootstrap>", line 2226, in _find_and_load_unlocked
  File "<frozen importlib._bootstrap>", line 1200, in _load_unlocked
  File "<frozen importlib._bootstrap>", line 1129, in _exec
  File "<frozen importlib._bootstrap>", line 1471, in exec_module
  File "<frozen importlib._bootstrap>", line 321, in _call_with_frames_removed
  File "/var/www/django/blog/urls.py", line 2, in <module>
    from . import views
  File "/var/www/django/blog/views.py", line 8
    Post.objects.filter(published_date__lte=timezone.now()).order_by('published_date')
       ^
IndentationError: expected an indented block
Performing system checks...

Unhandled exception in thread started by <function check_errors.<locals>.wrapper at 0x7f52983fe6a8>
Traceback (most recent call last):
  File "/var/www/django/myvenv/lib/python3.4/site-packages/django/utils/autoreload.py", line 228, in wrapper
    fn(*args, **kwargs)
  File "/var/www/django/myvenv/lib/python3.4/site-packages/django/core/management/commands/runserver.py", line 125, in inner_run
    self.check(display_num_errors=True)
  File "/var/www/django/myvenv/lib/python3.4/site-packages/django/core/management/base.py", line 359, in check
    include_deployment_checks=include_deployment_checks,
  File "/var/www/django/myvenv/lib/python3.4/site-packages/django/core/management/base.py", line 346, in _run_checks
    return checks.run_checks(**kwargs)
  File "/var/www/django/myvenv/lib/python3.4/site-packages/django/core/checks/registry.py", line 81, in run_checks
    new_errors = check(app_configs=app_configs)
  File "/var/www/django/myvenv/lib/python3.4/site-packages/django/core/checks/urls.py", line 16, in check_url_config
    return check_resolver(resolver)
  File "/var/www/django/myvenv/lib/python3.4/site-packages/django/core/checks/urls.py", line 26, in check_resolver
    return check_method()
  File "/var/www/django/myvenv/lib/python3.4/site-packages/django/urls/resolvers.py", line 254, in check
    for pattern in self.url_patterns:
  File "/var/www/django/myvenv/lib/python3.4/site-packages/django/utils/functional.py", line 35, in __get__
    res = instance.__dict__[self.name] = self.func(instance)
  File "/var/www/django/myvenv/lib/python3.4/site-packages/django/urls/resolvers.py", line 405, in url_patterns
    patterns = getattr(self.urlconf_module, "urlpatterns", self.urlconf_module)
  File "/var/www/django/myvenv/lib/python3.4/site-packages/django/utils/functional.py", line 35, in __get__
    res = instance.__dict__[self.name] = self.func(instance)
  File "/var/www/django/myvenv/lib/python3.4/site-packages/django/urls/resolvers.py", line 398, in urlconf_module
    return import_module(self.urlconf_name)
  File "/usr/lib/python3.4/importlib/__init__.py", line 109, in import_module
    return _bootstrap._gcd_import(name[level:], package, level)
  File "<frozen importlib._bootstrap>", line 2254, in _gcd_import
  File "<frozen importlib._bootstrap>", line 2237, in _find_and_load
  File "<frozen importlib._bootstrap>", line 2226, in _find_and_load_unlocked
  File "<frozen importlib._bootstrap>", line 1200, in _load_unlocked
  File "<frozen importlib._bootstrap>", line 1129, in _exec
  File "<frozen importlib._bootstrap>", line 1471, in exec_module
  File "<frozen importlib._bootstrap>", line 321, in _call_with_frames_removed
  File "/var/www/django/mysite/urls.py", line 10, in <module>
    url(r'', include('blog.urls')),
  File "/var/www/django/myvenv/lib/python3.4/site-packages/django/conf/urls/__init__.py", line 50, in include
    urlconf_module = import_module(urlconf_module)
  File "/usr/lib/python3.4/importlib/__init__.py", line 109, in import_module
    return _bootstrap._gcd_import(name[level:], package, level)
  File "<frozen importlib._bootstrap>", line 2254, in _gcd_import
  File "<frozen importlib._bootstrap>", line 2237, in _find_and_load
  File "<frozen importlib._bootstrap>", line 2226, in _find_and_load_unlocked
  File "<frozen importlib._bootstrap>", line 1200, in _load_unlocked
  File "<frozen importlib._bootstrap>", line 1129, in _exec
  File "<frozen importlib._bootstrap>", line 1471, in exec_module
  File "<frozen importlib._bootstrap>", line 321, in _call_with_frames_removed
  File "/var/www/django/blog/urls.py", line 2, in <module>
    from . import views
  File "/var/www/django/blog/views.py", line 8
    Post.objects.filter(published_date__lte=timezone.now()).order_by('published_date')
       ^
IndentationError: expected an indented block
Performing system checks...

Unhandled exception in thread started by <function check_errors.<locals>.wrapper at 0x7f8c2e7ba6a8>
Traceback (most recent call last):
  File "/var/www/django/myvenv/lib/python3.4/site-packages/django/utils/autoreload.py", line 228, in wrapper
    fn(*args, **kwargs)
  File "/var/www/django/myvenv/lib/python3.4/site-packages/django/core/management/commands/runserver.py", line 125, in inner_run
    self.check(display_num_errors=True)
  File "/var/www/django/myvenv/lib/python3.4/site-packages/django/core/management/base.py", line 359, in check
    include_deployment_checks=include_deployment_checks,
  File "/var/www/django/myvenv/lib/python3.4/site-packages/django/core/management/base.py", line 346, in _run_checks
    return checks.run_checks(**kwargs)
  File "/var/www/django/myvenv/lib/python3.4/site-packages/django/core/checks/registry.py", line 81, in run_checks
    new_errors = check(app_configs=app_configs)
  File "/var/www/django/myvenv/lib/python3.4/site-packages/django/core/checks/urls.py", line 16, in check_url_config
    return check_resolver(resolver)
  File "/var/www/django/myvenv/lib/python3.4/site-packages/django/core/checks/urls.py", line 26, in check_resolver
    return check_method()
  File "/var/www/django/myvenv/lib/python3.4/site-packages/django/urls/resolvers.py", line 254, in check
    for pattern in self.url_patterns:
  File "/var/www/django/myvenv/lib/python3.4/site-packages/django/utils/functional.py", line 35, in __get__
    res = instance.__dict__[self.name] = self.func(instance)
  File "/var/www/django/myvenv/lib/python3.4/site-packages/django/urls/resolvers.py", line 405, in url_patterns
    patterns = getattr(self.urlconf_module, "urlpatterns", self.urlconf_module)
  File "/var/www/django/myvenv/lib/python3.4/site-packages/django/utils/functional.py", line 35, in __get__
    res = instance.__dict__[self.name] = self.func(instance)
  File "/var/www/django/myvenv/lib/python3.4/site-packages/django/urls/resolvers.py", line 398, in urlconf_module
    return import_module(self.urlconf_name)
  File "/usr/lib/python3.4/importlib/__init__.py", line 109, in import_module
    return _bootstrap._gcd_import(name[level:], package, level)
  File "<frozen importlib._bootstrap>", line 2254, in _gcd_import
  File "<frozen importlib._bootstrap>", line 2237, in _find_and_load
  File "<frozen importlib._bootstrap>", line 2226, in _find_and_load_unlocked
  File "<frozen importlib._bootstrap>", line 1200, in _load_unlocked
  File "<frozen importlib._bootstrap>", line 1129, in _exec
  File "<frozen importlib._bootstrap>", line 1471, in exec_module
  File "<frozen importlib._bootstrap>", line 321, in _call_with_frames_removed
  File "/var/www/django/mysite/urls.py", line 10, in <module>
    url(r'', include('blog.urls')),
  File "/var/www/django/myvenv/lib/python3.4/site-packages/django/conf/urls/__init__.py", line 50, in include
    urlconf_module = import_module(urlconf_module)
  File "/usr/lib/python3.4/importlib/__init__.py", line 109, in import_module
    return _bootstrap._gcd_import(name[level:], package, level)
  File "<frozen importlib._bootstrap>", line 2254, in _gcd_import
  File "<frozen importlib._bootstrap>", line 2237, in _find_and_load
  File "<frozen importlib._bootstrap>", line 2226, in _find_and_load_unlocked
  File "<frozen importlib._bootstrap>", line 1200, in _load_unlocked
  File "<frozen importlib._bootstrap>", line 1129, in _exec
  File "<frozen importlib._bootstrap>", line 1471, in exec_module
  File "<frozen importlib._bootstrap>", line 321, in _call_with_frames_removed
  File "/var/www/django/blog/urls.py", line 2, in <module>
    from . import views
  File "/var/www/django/blog/views.py", line 8
    Post.objects.filter(published_date__lte=timezone.now()).order_by('published_date')
       ^
IndentationError: expected an indented block
Performing system checks...

[09/Nov/2017 14:38:49] "GET /admin/ HTTP/1.1" 200 5283
Not Found: /favicon.ico
[09/Nov/2017 14:38:49] "GET /favicon.ico HTTP/1.1" 404 2142
Performing system checks...

System check identified no issues (0 silenced).
November 09, 2017 - 14:38:46
Django version 1.11.6, using settings 'mysite.settings'
Starting development server at http://192.168.1.123:8000/
Quit the server with CONTROL-C.
Unhandled exception in thread started by <function check_errors.<locals>.wrapper at 0x7fc4de2396a8>
Traceback (most recent call last):
  File "/var/www/django/myvenv/lib/python3.4/site-packages/django/utils/autoreload.py", line 228, in wrapper
    fn(*args, **kwargs)
  File "/var/www/django/myvenv/lib/python3.4/site-packages/django/core/management/commands/runserver.py", line 125, in inner_run
    self.check(display_num_errors=True)
  File "/var/www/django/myvenv/lib/python3.4/site-packages/django/core/management/base.py", line 359, in check
    include_deployment_checks=include_deployment_checks,
  File "/var/www/django/myvenv/lib/python3.4/site-packages/django/core/management/base.py", line 346, in _run_checks
    return checks.run_checks(**kwargs)
  File "/var/www/django/myvenv/lib/python3.4/site-packages/django/core/checks/registry.py", line 81, in run_checks
    new_errors = check(app_configs=app_configs)
  File "/var/www/django/myvenv/lib/python3.4/site-packages/django/core/checks/urls.py", line 16, in check_url_config
    return check_resolver(resolver)
  File "/var/www/django/myvenv/lib/python3.4/site-packages/django/core/checks/urls.py", line 26, in check_resolver
    return check_method()
  File "/var/www/django/myvenv/lib/python3.4/site-packages/django/urls/resolvers.py", line 254, in check
    for pattern in self.url_patterns:
  File "/var/www/django/myvenv/lib/python3.4/site-packages/django/utils/functional.py", line 35, in __get__
    res = instance.__dict__[self.name] = self.func(instance)
  File "/var/www/django/myvenv/lib/python3.4/site-packages/django/urls/resolvers.py", line 405, in url_patterns
    patterns = getattr(self.urlconf_module, "urlpatterns", self.urlconf_module)
  File "/var/www/django/myvenv/lib/python3.4/site-packages/django/utils/functional.py", line 35, in __get__
    res = instance.__dict__[self.name] = self.func(instance)
  File "/var/www/django/myvenv/lib/python3.4/site-packages/django/urls/resolvers.py", line 398, in urlconf_module
    return import_module(self.urlconf_name)
  File "/usr/lib/python3.4/importlib/__init__.py", line 109, in import_module
    return _bootstrap._gcd_import(name[level:], package, level)
  File "<frozen importlib._bootstrap>", line 2254, in _gcd_import
  File "<frozen importlib._bootstrap>", line 2237, in _find_and_load
  File "<frozen importlib._bootstrap>", line 2226, in _find_and_load_unlocked
  File "<frozen importlib._bootstrap>", line 1200, in _load_unlocked
  File "<frozen importlib._bootstrap>", line 1129, in _exec
  File "<frozen importlib._bootstrap>", line 1471, in exec_module
  File "<frozen importlib._bootstrap>", line 321, in _call_with_frames_removed
  File "/var/www/django/mysite/urls.py", line 10, in <module>
    url(r'', include('blog.urls')),
  File "/var/www/django/myvenv/lib/python3.4/site-packages/django/conf/urls/__init__.py", line 50, in include
    urlconf_module = import_module(urlconf_module)
  File "/usr/lib/python3.4/importlib/__init__.py", line 109, in import_module
    return _bootstrap._gcd_import(name[level:], package, level)
  File "<frozen importlib._bootstrap>", line 2254, in _gcd_import
  File "<frozen importlib._bootstrap>", line 2237, in _find_and_load
  File "<frozen importlib._bootstrap>", line 2226, in _find_and_load_unlocked
  File "<frozen importlib._bootstrap>", line 1200, in _load_unlocked
  File "<frozen importlib._bootstrap>", line 1129, in _exec
  File "<frozen importlib._bootstrap>", line 1471, in exec_module
  File "<frozen importlib._bootstrap>", line 321, in _call_with_frames_removed
  File "/var/www/django/blog/urls.py", line 2, in <module>
    from . import views
  File "/var/www/django/blog/views.py", line 8
    Post.objects.filter(published_date__lte=timezone.now()).order_by('published_date')
       ^
IndentationError: expected an indented block
Performing system checks...

Unhandled exception in thread started by <function check_errors.<locals>.wrapper at 0x7f83f8c1d6a8>
Traceback (most recent call last):
  File "/var/www/django/myvenv/lib/python3.4/site-packages/django/utils/autoreload.py", line 228, in wrapper
    fn(*args, **kwargs)
  File "/var/www/django/myvenv/lib/python3.4/site-packages/django/core/management/commands/runserver.py", line 125, in inner_run
    self.check(display_num_errors=True)
  File "/var/www/django/myvenv/lib/python3.4/site-packages/django/core/management/base.py", line 359, in check
    include_deployment_checks=include_deployment_checks,
  File "/var/www/django/myvenv/lib/python3.4/site-packages/django/core/management/base.py", line 346, in _run_checks
    return checks.run_checks(**kwargs)
  File "/var/www/django/myvenv/lib/python3.4/site-packages/django/core/checks/registry.py", line 81, in run_checks
    new_errors = check(app_configs=app_configs)
  File "/var/www/django/myvenv/lib/python3.4/site-packages/django/core/checks/urls.py", line 16, in check_url_config
    return check_resolver(resolver)
  File "/var/www/django/myvenv/lib/python3.4/site-packages/django/core/checks/urls.py", line 26, in check_resolver
    return check_method()
  File "/var/www/django/myvenv/lib/python3.4/site-packages/django/urls/resolvers.py", line 254, in check
    for pattern in self.url_patterns:
  File "/var/www/django/myvenv/lib/python3.4/site-packages/django/utils/functional.py", line 35, in __get__
    res = instance.__dict__[self.name] = self.func(instance)
  File "/var/www/django/myvenv/lib/python3.4/site-packages/django/urls/resolvers.py", line 405, in url_patterns
    patterns = getattr(self.urlconf_module, "urlpatterns", self.urlconf_module)
  File "/var/www/django/myvenv/lib/python3.4/site-packages/django/utils/functional.py", line 35, in __get__
    res = instance.__dict__[self.name] = self.func(instance)
  File "/var/www/django/myvenv/lib/python3.4/site-packages/django/urls/resolvers.py", line 398, in urlconf_module
    return import_module(self.urlconf_name)
  File "/usr/lib/python3.4/importlib/__init__.py", line 109, in import_module
    return _bootstrap._gcd_import(name[level:], package, level)
  File "<frozen importlib._bootstrap>", line 2254, in _gcd_import
  File "<frozen importlib._bootstrap>", line 2237, in _find_and_load
  File "<frozen importlib._bootstrap>", line 2226, in _find_and_load_unlocked
  File "<frozen importlib._bootstrap>", line 1200, in _load_unlocked
  File "<frozen importlib._bootstrap>", line 1129, in _exec
  File "<frozen importlib._bootstrap>", line 1471, in exec_module
  File "<frozen importlib._bootstrap>", line 321, in _call_with_frames_removed
  File "/var/www/django/mysite/urls.py", line 10, in <module>
    url(r'', include('blog.urls')),
  File "/var/www/django/myvenv/lib/python3.4/site-packages/django/conf/urls/__init__.py", line 50, in include
    urlconf_module = import_module(urlconf_module)
  File "/usr/lib/python3.4/importlib/__init__.py", line 109, in import_module
    return _bootstrap._gcd_import(name[level:], package, level)
  File "<frozen importlib._bootstrap>", line 2254, in _gcd_import
  File "<frozen importlib._bootstrap>", line 2237, in _find_and_load
  File "<frozen importlib._bootstrap>", line 2226, in _find_and_load_unlocked
  File "<frozen importlib._bootstrap>", line 1200, in _load_unlocked
  File "<frozen importlib._bootstrap>", line 1129, in _exec
  File "<frozen importlib._bootstrap>", line 1471, in exec_module
  File "<frozen importlib._bootstrap>", line 321, in _call_with_frames_removed
  File "/var/www/django/blog/urls.py", line 2, in <module>
    from . import views
  File "/var/www/django/blog/views.py", line 8
    posts = Post.objects.filter(published_date__lte=timezone.now()).order_by('published_date')
        ^
IndentationError: expected an indented block
Performing system checks...

Unhandled exception in thread started by <function check_errors.<locals>.wrapper at 0x7f5a015f16a8>
Traceback (most recent call last):
  File "/var/www/django/myvenv/lib/python3.4/site-packages/django/utils/autoreload.py", line 228, in wrapper
    fn(*args, **kwargs)
  File "/var/www/django/myvenv/lib/python3.4/site-packages/django/core/management/commands/runserver.py", line 125, in inner_run
    self.check(display_num_errors=True)
  File "/var/www/django/myvenv/lib/python3.4/site-packages/django/core/management/base.py", line 359, in check
    include_deployment_checks=include_deployment_checks,
  File "/var/www/django/myvenv/lib/python3.4/site-packages/django/core/management/base.py", line 346, in _run_checks
    return checks.run_checks(**kwargs)
  File "/var/www/django/myvenv/lib/python3.4/site-packages/django/core/checks/registry.py", line 81, in run_checks
    new_errors = check(app_configs=app_configs)
  File "/var/www/django/myvenv/lib/python3.4/site-packages/django/core/checks/urls.py", line 16, in check_url_config
    return check_resolver(resolver)
  File "/var/www/django/myvenv/lib/python3.4/site-packages/django/core/checks/urls.py", line 26, in check_resolver
    return check_method()
  File "/var/www/django/myvenv/lib/python3.4/site-packages/django/urls/resolvers.py", line 254, in check
    for pattern in self.url_patterns:
  File "/var/www/django/myvenv/lib/python3.4/site-packages/django/utils/functional.py", line 35, in __get__
    res = instance.__dict__[self.name] = self.func(instance)
  File "/var/www/django/myvenv/lib/python3.4/site-packages/django/urls/resolvers.py", line 405, in url_patterns
    patterns = getattr(self.urlconf_module, "urlpatterns", self.urlconf_module)
  File "/var/www/django/myvenv/lib/python3.4/site-packages/django/utils/functional.py", line 35, in __get__
    res = instance.__dict__[self.name] = self.func(instance)
  File "/var/www/django/myvenv/lib/python3.4/site-packages/django/urls/resolvers.py", line 398, in urlconf_module
    return import_module(self.urlconf_name)
  File "/usr/lib/python3.4/importlib/__init__.py", line 109, in import_module
    return _bootstrap._gcd_import(name[level:], package, level)
  File "<frozen importlib._bootstrap>", line 2254, in _gcd_import
  File "<frozen importlib._bootstrap>", line 2237, in _find_and_load
  File "<frozen importlib._bootstrap>", line 2226, in _find_and_load_unlocked
  File "<frozen importlib._bootstrap>", line 1200, in _load_unlocked
  File "<frozen importlib._bootstrap>", line 1129, in _exec
  File "<frozen importlib._bootstrap>", line 1471, in exec_module
  File "<frozen importlib._bootstrap>", line 321, in _call_with_frames_removed
  File "/var/www/django/mysite/urls.py", line 10, in <module>
    url(r'', include('blog.urls')),
  File "/var/www/django/myvenv/lib/python3.4/site-packages/django/conf/urls/__init__.py", line 50, in include
    urlconf_module = import_module(urlconf_module)
  File "/usr/lib/python3.4/importlib/__init__.py", line 109, in import_module
    return _bootstrap._gcd_import(name[level:], package, level)
  File "<frozen importlib._bootstrap>", line 2254, in _gcd_import
  File "<frozen importlib._bootstrap>", line 2237, in _find_and_load
  File "<frozen importlib._bootstrap>", line 2226, in _find_and_load_unlocked
  File "<frozen importlib._bootstrap>", line 1200, in _load_unlocked
  File "<frozen importlib._bootstrap>", line 1129, in _exec
  File "<frozen importlib._bootstrap>", line 1471, in exec_module
  File "<frozen importlib._bootstrap>", line 321, in _call_with_frames_removed
  File "/var/www/django/blog/urls.py", line 2, in <module>
    from . import views
  File "/var/www/django/blog/views.py", line 10
    return render(request, 'blog/post_list.html', {'posts': posts})
         ^
IndentationError: expected an indented block
Performing system checks...

Unhandled exception in thread started by <function check_errors.<locals>.wrapper at 0x7f365ee7c6a8>
Traceback (most recent call last):
  File "/var/www/django/myvenv/lib/python3.4/site-packages/django/utils/autoreload.py", line 228, in wrapper
    fn(*args, **kwargs)
  File "/var/www/django/myvenv/lib/python3.4/site-packages/django/core/management/commands/runserver.py", line 125, in inner_run
    self.check(display_num_errors=True)
  File "/var/www/django/myvenv/lib/python3.4/site-packages/django/core/management/base.py", line 359, in check
    include_deployment_checks=include_deployment_checks,
  File "/var/www/django/myvenv/lib/python3.4/site-packages/django/core/management/base.py", line 346, in _run_checks
    return checks.run_checks(**kwargs)
  File "/var/www/django/myvenv/lib/python3.4/site-packages/django/core/checks/registry.py", line 81, in run_checks
    new_errors = check(app_configs=app_configs)
  File "/var/www/django/myvenv/lib/python3.4/site-packages/django/core/checks/urls.py", line 16, in check_url_config
    return check_resolver(resolver)
  File "/var/www/django/myvenv/lib/python3.4/site-packages/django/core/checks/urls.py", line 26, in check_resolver
    return check_method()
  File "/var/www/django/myvenv/lib/python3.4/site-packages/django/urls/resolvers.py", line 254, in check
    for pattern in self.url_patterns:
  File "/var/www/django/myvenv/lib/python3.4/site-packages/django/utils/functional.py", line 35, in __get__
    res = instance.__dict__[self.name] = self.func(instance)
  File "/var/www/django/myvenv/lib/python3.4/site-packages/django/urls/resolvers.py", line 405, in url_patterns
    patterns = getattr(self.urlconf_module, "urlpatterns", self.urlconf_module)
  File "/var/www/django/myvenv/lib/python3.4/site-packages/django/utils/functional.py", line 35, in __get__
    res = instance.__dict__[self.name] = self.func(instance)
  File "/var/www/django/myvenv/lib/python3.4/site-packages/django/urls/resolvers.py", line 398, in urlconf_module
    return import_module(self.urlconf_name)
  File "/usr/lib/python3.4/importlib/__init__.py", line 109, in import_module
    return _bootstrap._gcd_import(name[level:], package, level)
  File "<frozen importlib._bootstrap>", line 2254, in _gcd_import
  File "<frozen importlib._bootstrap>", line 2237, in _find_and_load
  File "<frozen importlib._bootstrap>", line 2226, in _find_and_load_unlocked
  File "<frozen importlib._bootstrap>", line 1200, in _load_unlocked
  File "<frozen importlib._bootstrap>", line 1129, in _exec
  File "<frozen importlib._bootstrap>", line 1471, in exec_module
  File "<frozen importlib._bootstrap>", line 321, in _call_with_frames_removed
  File "/var/www/django/mysite/urls.py", line 10, in <module>
    url(r'', include('blog.urls')),
  File "/var/www/django/myvenv/lib/python3.4/site-packages/django/conf/urls/__init__.py", line 50, in include
    urlconf_module = import_module(urlconf_module)
  File "/usr/lib/python3.4/importlib/__init__.py", line 109, in import_module
    return _bootstrap._gcd_import(name[level:], package, level)
  File "<frozen importlib._bootstrap>", line 2254, in _gcd_import
  File "<frozen importlib._bootstrap>", line 2237, in _find_and_load
  File "<frozen importlib._bootstrap>", line 2226, in _find_and_load_unlocked
  File "<frozen importlib._bootstrap>", line 1200, in _load_unlocked
  File "<frozen importlib._bootstrap>", line 1129, in _exec
  File "<frozen importlib._bootstrap>", line 1471, in exec_module
  File "<frozen importlib._bootstrap>", line 321, in _call_with_frames_removed
  File "/var/www/django/blog/urls.py", line 2, in <module>
    from . import views
  File "/var/www/django/blog/views.py", line 10
    return render(request, 'blog/post_list.html', {'posts': posts})
         ^
IndentationError: expected an indented block
Performing system checks...

[09/Nov/2017 14:44:55] "GET / HTTP/1.1" 200 216
Not Found: /favicon.ico
[09/Nov/2017 14:44:55] "GET /favicon.ico HTTP/1.1" 404 2142
Performing system checks...

System check identified no issues (0 silenced).
November 09, 2017 - 14:44:54
Django version 1.11.6, using settings 'mysite.settings'
Starting development server at http://192.168.1.123:8000/
Quit the server with CONTROL-C.
[09/Nov/2017 14:45:04] "GET / HTTP/1.1" 200 216
Not Found: /favicon.ico
[09/Nov/2017 14:45:04] "GET /favicon.ico HTTP/1.1" 404 2142
Performing system checks...

System check identified no issues (0 silenced).
November 09, 2017 - 14:45:04
Django version 1.11.6, using settings 'mysite.settings'
Starting development server at http://192.168.1.123:8000/
Quit the server with CONTROL-C.
Unhandled exception in thread started by <function check_errors.<locals>.wrapper at 0x7f960e2a56a8>
Traceback (most recent call last):
  File "/var/www/django/myvenv/lib/python3.4/site-packages/django/utils/autoreload.py", line 228, in wrapper
    fn(*args, **kwargs)
  File "/var/www/django/myvenv/lib/python3.4/site-packages/django/core/management/commands/runserver.py", line 125, in inner_run
    self.check(display_num_errors=True)
  File "/var/www/django/myvenv/lib/python3.4/site-packages/django/core/management/base.py", line 359, in check
    include_deployment_checks=include_deployment_checks,
  File "/var/www/django/myvenv/lib/python3.4/site-packages/django/core/management/base.py", line 346, in _run_checks
    return checks.run_checks(**kwargs)
  File "/var/www/django/myvenv/lib/python3.4/site-packages/django/core/checks/registry.py", line 81, in run_checks
    new_errors = check(app_configs=app_configs)
  File "/var/www/django/myvenv/lib/python3.4/site-packages/django/core/checks/urls.py", line 16, in check_url_config
    return check_resolver(resolver)
  File "/var/www/django/myvenv/lib/python3.4/site-packages/django/core/checks/urls.py", line 26, in check_resolver
    return check_method()
  File "/var/www/django/myvenv/lib/python3.4/site-packages/django/urls/resolvers.py", line 254, in check
    for pattern in self.url_patterns:
  File "/var/www/django/myvenv/lib/python3.4/site-packages/django/utils/functional.py", line 35, in __get__
    res = instance.__dict__[self.name] = self.func(instance)
  File "/var/www/django/myvenv/lib/python3.4/site-packages/django/urls/resolvers.py", line 405, in url_patterns
    patterns = getattr(self.urlconf_module, "urlpatterns", self.urlconf_module)
  File "/var/www/django/myvenv/lib/python3.4/site-packages/django/utils/functional.py", line 35, in __get__
    res = instance.__dict__[self.name] = self.func(instance)
  File "/var/www/django/myvenv/lib/python3.4/site-packages/django/urls/resolvers.py", line 398, in urlconf_module
    return import_module(self.urlconf_name)
  File "/usr/lib/python3.4/importlib/__init__.py", line 109, in import_module
    return _bootstrap._gcd_import(name[level:], package, level)
  File "<frozen importlib._bootstrap>", line 2254, in _gcd_import
  File "<frozen importlib._bootstrap>", line 2237, in _find_and_load
  File "<frozen importlib._bootstrap>", line 2226, in _find_and_load_unlocked
  File "<frozen importlib._bootstrap>", line 1200, in _load_unlocked
  File "<frozen importlib._bootstrap>", line 1129, in _exec
  File "<frozen importlib._bootstrap>", line 1471, in exec_module
  File "<frozen importlib._bootstrap>", line 321, in _call_with_frames_removed
  File "/var/www/django/mysite/urls.py", line 10, in <module>
    url(r'', include('blog.urls')),
  File "/var/www/django/myvenv/lib/python3.4/site-packages/django/conf/urls/__init__.py", line 50, in include
    urlconf_module = import_module(urlconf_module)
  File "/usr/lib/python3.4/importlib/__init__.py", line 109, in import_module
    return _bootstrap._gcd_import(name[level:], package, level)
  File "<frozen importlib._bootstrap>", line 2254, in _gcd_import
  File "<frozen importlib._bootstrap>", line 2237, in _find_and_load
  File "<frozen importlib._bootstrap>", line 2226, in _find_and_load_unlocked
  File "<frozen importlib._bootstrap>", line 1200, in _load_unlocked
  File "<frozen importlib._bootstrap>", line 1129, in _exec
  File "<frozen importlib._bootstrap>", line 1471, in exec_module
  File "<frozen importlib._bootstrap>", line 321, in _call_with_frames_removed
  File "/var/www/django/blog/urls.py", line 2, in <module>
    from . import views
  File "/var/www/django/blog/views.py", line 8
    posts = Post.objects.filter(published_date__lte=timezone.now()).order_by('published_date')
        ^
IndentationError: expected an indented block
Performing system checks...

Unhandled exception in thread started by <function check_errors.<locals>.wrapper at 0x7f240815a6a8>
Traceback (most recent call last):
  File "/var/www/django/myvenv/lib/python3.4/site-packages/django/utils/autoreload.py", line 228, in wrapper
    fn(*args, **kwargs)
  File "/var/www/django/myvenv/lib/python3.4/site-packages/django/core/management/commands/runserver.py", line 125, in inner_run
    self.check(display_num_errors=True)
  File "/var/www/django/myvenv/lib/python3.4/site-packages/django/core/management/base.py", line 359, in check
    include_deployment_checks=include_deployment_checks,
  File "/var/www/django/myvenv/lib/python3.4/site-packages/django/core/management/base.py", line 346, in _run_checks
    return checks.run_checks(**kwargs)
  File "/var/www/django/myvenv/lib/python3.4/site-packages/django/core/checks/registry.py", line 81, in run_checks
    new_errors = check(app_configs=app_configs)
  File "/var/www/django/myvenv/lib/python3.4/site-packages/django/core/checks/urls.py", line 16, in check_url_config
    return check_resolver(resolver)
  File "/var/www/django/myvenv/lib/python3.4/site-packages/django/core/checks/urls.py", line 26, in check_resolver
    return check_method()
  File "/var/www/django/myvenv/lib/python3.4/site-packages/django/urls/resolvers.py", line 254, in check
    for pattern in self.url_patterns:
  File "/var/www/django/myvenv/lib/python3.4/site-packages/django/utils/functional.py", line 35, in __get__
    res = instance.__dict__[self.name] = self.func(instance)
  File "/var/www/django/myvenv/lib/python3.4/site-packages/django/urls/resolvers.py", line 405, in url_patterns
    patterns = getattr(self.urlconf_module, "urlpatterns", self.urlconf_module)
  File "/var/www/django/myvenv/lib/python3.4/site-packages/django/utils/functional.py", line 35, in __get__
    res = instance.__dict__[self.name] = self.func(instance)
  File "/var/www/django/myvenv/lib/python3.4/site-packages/django/urls/resolvers.py", line 398, in urlconf_module
    return import_module(self.urlconf_name)
  File "/usr/lib/python3.4/importlib/__init__.py", line 109, in import_module
    return _bootstrap._gcd_import(name[level:], package, level)
  File "<frozen importlib._bootstrap>", line 2254, in _gcd_import
  File "<frozen importlib._bootstrap>", line 2237, in _find_and_load
  File "<frozen importlib._bootstrap>", line 2226, in _find_and_load_unlocked
  File "<frozen importlib._bootstrap>", line 1200, in _load_unlocked
  File "<frozen importlib._bootstrap>", line 1129, in _exec
  File "<frozen importlib._bootstrap>", line 1471, in exec_module
  File "<frozen importlib._bootstrap>", line 321, in _call_with_frames_removed
  File "/var/www/django/mysite/urls.py", line 10, in <module>
    url(r'', include('blog.urls')),
  File "/var/www/django/myvenv/lib/python3.4/site-packages/django/conf/urls/__init__.py", line 50, in include
    urlconf_module = import_module(urlconf_module)
  File "/usr/lib/python3.4/importlib/__init__.py", line 109, in import_module
    return _bootstrap._gcd_import(name[level:], package, level)
  File "<frozen importlib._bootstrap>", line 2254, in _gcd_import
  File "<frozen importlib._bootstrap>", line 2237, in _find_and_load
  File "<frozen importlib._bootstrap>", line 2226, in _find_and_load_unlocked
  File "<frozen importlib._bootstrap>", line 1200, in _load_unlocked
  File "<frozen importlib._bootstrap>", line 1129, in _exec
  File "<frozen importlib._bootstrap>", line 1471, in exec_module
  File "<frozen importlib._bootstrap>", line 321, in _call_with_frames_removed
  File "/var/www/django/blog/urls.py", line 2, in <module>
    from . import views
  File "/var/www/django/blog/views.py", line 8
    posts = Post.objects.filter(published_date__lte=timezone.now()).order_by('published_date')
        ^
IndentationError: expected an indented block
Performing system checks...

Unhandled exception in thread started by <function check_errors.<locals>.wrapper at 0x7f40270b06a8>
Traceback (most recent call last):
  File "/var/www/django/myvenv/lib/python3.4/site-packages/django/utils/autoreload.py", line 228, in wrapper
    fn(*args, **kwargs)
  File "/var/www/django/myvenv/lib/python3.4/site-packages/django/core/management/commands/runserver.py", line 125, in inner_run
    self.check(display_num_errors=True)
  File "/var/www/django/myvenv/lib/python3.4/site-packages/django/core/management/base.py", line 359, in check
    include_deployment_checks=include_deployment_checks,
  File "/var/www/django/myvenv/lib/python3.4/site-packages/django/core/management/base.py", line 346, in _run_checks
    return checks.run_checks(**kwargs)
  File "/var/www/django/myvenv/lib/python3.4/site-packages/django/core/checks/registry.py", line 81, in run_checks
    new_errors = check(app_configs=app_configs)
  File "/var/www/django/myvenv/lib/python3.4/site-packages/django/core/checks/urls.py", line 16, in check_url_config
    return check_resolver(resolver)
  File "/var/www/django/myvenv/lib/python3.4/site-packages/django/core/checks/urls.py", line 26, in check_resolver
    return check_method()
  File "/var/www/django/myvenv/lib/python3.4/site-packages/django/urls/resolvers.py", line 254, in check
    for pattern in self.url_patterns:
  File "/var/www/django/myvenv/lib/python3.4/site-packages/django/utils/functional.py", line 35, in __get__
    res = instance.__dict__[self.name] = self.func(instance)
  File "/var/www/django/myvenv/lib/python3.4/site-packages/django/urls/resolvers.py", line 405, in url_patterns
    patterns = getattr(self.urlconf_module, "urlpatterns", self.urlconf_module)
  File "/var/www/django/myvenv/lib/python3.4/site-packages/django/utils/functional.py", line 35, in __get__
    res = instance.__dict__[self.name] = self.func(instance)
  File "/var/www/django/myvenv/lib/python3.4/site-packages/django/urls/resolvers.py", line 398, in urlconf_module
    return import_module(self.urlconf_name)
  File "/usr/lib/python3.4/importlib/__init__.py", line 109, in import_module
    return _bootstrap._gcd_import(name[level:], package, level)
  File "<frozen importlib._bootstrap>", line 2254, in _gcd_import
  File "<frozen importlib._bootstrap>", line 2237, in _find_and_load
  File "<frozen importlib._bootstrap>", line 2226, in _find_and_load_unlocked
  File "<frozen importlib._bootstrap>", line 1200, in _load_unlocked
  File "<frozen importlib._bootstrap>", line 1129, in _exec
  File "<frozen importlib._bootstrap>", line 1471, in exec_module
  File "<frozen importlib._bootstrap>", line 321, in _call_with_frames_removed
  File "/var/www/django/mysite/urls.py", line 10, in <module>
    url(r'', include('blog.urls')),
  File "/var/www/django/myvenv/lib/python3.4/site-packages/django/conf/urls/__init__.py", line 50, in include
    urlconf_module = import_module(urlconf_module)
  File "/usr/lib/python3.4/importlib/__init__.py", line 109, in import_module
    return _bootstrap._gcd_import(name[level:], package, level)
  File "<frozen importlib._bootstrap>", line 2254, in _gcd_import
  File "<frozen importlib._bootstrap>", line 2237, in _find_and_load
  File "<frozen importlib._bootstrap>", line 2226, in _find_and_load_unlocked
  File "<frozen importlib._bootstrap>", line 1200, in _load_unlocked
  File "<frozen importlib._bootstrap>", line 1129, in _exec
  File "<frozen importlib._bootstrap>", line 1471, in exec_module
  File "<frozen importlib._bootstrap>", line 321, in _call_with_frames_removed
  File "/var/www/django/blog/urls.py", line 2, in <module>
    from . import views
  File "/var/www/django/blog/views.py", line 8
    posts = Post.objects.filter(published_date__lte=timezone.now()).order_by('published_date')
        ^
IndentationError: expected an indented block
Performing system checks...

Unhandled exception in thread started by <function check_errors.<locals>.wrapper at 0x7f3dcf0916a8>
Traceback (most recent call last):
  File "/var/www/django/myvenv/lib/python3.4/site-packages/django/utils/autoreload.py", line 228, in wrapper
    fn(*args, **kwargs)
  File "/var/www/django/myvenv/lib/python3.4/site-packages/django/core/management/commands/runserver.py", line 125, in inner_run
    self.check(display_num_errors=True)
  File "/var/www/django/myvenv/lib/python3.4/site-packages/django/core/management/base.py", line 359, in check
    include_deployment_checks=include_deployment_checks,
  File "/var/www/django/myvenv/lib/python3.4/site-packages/django/core/management/base.py", line 346, in _run_checks
    return checks.run_checks(**kwargs)
  File "/var/www/django/myvenv/lib/python3.4/site-packages/django/core/checks/registry.py", line 81, in run_checks
    new_errors = check(app_configs=app_configs)
  File "/var/www/django/myvenv/lib/python3.4/site-packages/django/core/checks/urls.py", line 16, in check_url_config
    return check_resolver(resolver)
  File "/var/www/django/myvenv/lib/python3.4/site-packages/django/core/checks/urls.py", line 26, in check_resolver
    return check_method()
  File "/var/www/django/myvenv/lib/python3.4/site-packages/django/urls/resolvers.py", line 254, in check
    for pattern in self.url_patterns:
  File "/var/www/django/myvenv/lib/python3.4/site-packages/django/utils/functional.py", line 35, in __get__
    res = instance.__dict__[self.name] = self.func(instance)
  File "/var/www/django/myvenv/lib/python3.4/site-packages/django/urls/resolvers.py", line 405, in url_patterns
    patterns = getattr(self.urlconf_module, "urlpatterns", self.urlconf_module)
  File "/var/www/django/myvenv/lib/python3.4/site-packages/django/utils/functional.py", line 35, in __get__
    res = instance.__dict__[self.name] = self.func(instance)
  File "/var/www/django/myvenv/lib/python3.4/site-packages/django/urls/resolvers.py", line 398, in urlconf_module
    return import_module(self.urlconf_name)
  File "/usr/lib/python3.4/importlib/__init__.py", line 109, in import_module
    return _bootstrap._gcd_import(name[level:], package, level)
  File "<frozen importlib._bootstrap>", line 2254, in _gcd_import
  File "<frozen importlib._bootstrap>", line 2237, in _find_and_load
  File "<frozen importlib._bootstrap>", line 2226, in _find_and_load_unlocked
  File "<frozen importlib._bootstrap>", line 1200, in _load_unlocked
  File "<frozen importlib._bootstrap>", line 1129, in _exec
  File "<frozen importlib._bootstrap>", line 1471, in exec_module
  File "<frozen importlib._bootstrap>", line 321, in _call_with_frames_removed
  File "/var/www/django/mysite/urls.py", line 10, in <module>
    url(r'', include('blog.urls')),
  File "/var/www/django/myvenv/lib/python3.4/site-packages/django/conf/urls/__init__.py", line 50, in include
    urlconf_module = import_module(urlconf_module)
  File "/usr/lib/python3.4/importlib/__init__.py", line 109, in import_module
    return _bootstrap._gcd_import(name[level:], package, level)
  File "<frozen importlib._bootstrap>", line 2254, in _gcd_import
  File "<frozen importlib._bootstrap>", line 2237, in _find_and_load
  File "<frozen importlib._bootstrap>", line 2226, in _find_and_load_unlocked
  File "<frozen importlib._bootstrap>", line 1200, in _load_unlocked
  File "<frozen importlib._bootstrap>", line 1129, in _exec
  File "<frozen importlib._bootstrap>", line 1471, in exec_module
  File "<frozen importlib._bootstrap>", line 321, in _call_with_frames_removed
  File "/var/www/django/blog/urls.py", line 2, in <module>
    from . import views
  File "/var/www/django/blog/views.py", line 8
    posts = Post.objects.filter(published_date__lte=timezone.now()).order_by('published_date')
        ^
IndentationError: expected an indented block
Performing system checks...

Unhandled exception in thread started by <function check_errors.<locals>.wrapper at 0x7f81e672c6a8>
Traceback (most recent call last):
  File "/var/www/django/myvenv/lib/python3.4/site-packages/django/utils/autoreload.py", line 228, in wrapper
    fn(*args, **kwargs)
  File "/var/www/django/myvenv/lib/python3.4/site-packages/django/core/management/commands/runserver.py", line 125, in inner_run
    self.check(display_num_errors=True)
  File "/var/www/django/myvenv/lib/python3.4/site-packages/django/core/management/base.py", line 359, in check
    include_deployment_checks=include_deployment_checks,
  File "/var/www/django/myvenv/lib/python3.4/site-packages/django/core/management/base.py", line 346, in _run_checks
    return checks.run_checks(**kwargs)
  File "/var/www/django/myvenv/lib/python3.4/site-packages/django/core/checks/registry.py", line 81, in run_checks
    new_errors = check(app_configs=app_configs)
  File "/var/www/django/myvenv/lib/python3.4/site-packages/django/core/checks/urls.py", line 16, in check_url_config
    return check_resolver(resolver)
  File "/var/www/django/myvenv/lib/python3.4/site-packages/django/core/checks/urls.py", line 26, in check_resolver
    return check_method()
  File "/var/www/django/myvenv/lib/python3.4/site-packages/django/urls/resolvers.py", line 254, in check
    for pattern in self.url_patterns:
  File "/var/www/django/myvenv/lib/python3.4/site-packages/django/utils/functional.py", line 35, in __get__
    res = instance.__dict__[self.name] = self.func(instance)
  File "/var/www/django/myvenv/lib/python3.4/site-packages/django/urls/resolvers.py", line 405, in url_patterns
    patterns = getattr(self.urlconf_module, "urlpatterns", self.urlconf_module)
  File "/var/www/django/myvenv/lib/python3.4/site-packages/django/utils/functional.py", line 35, in __get__
    res = instance.__dict__[self.name] = self.func(instance)
  File "/var/www/django/myvenv/lib/python3.4/site-packages/django/urls/resolvers.py", line 398, in urlconf_module
    return import_module(self.urlconf_name)
  File "/usr/lib/python3.4/importlib/__init__.py", line 109, in import_module
    return _bootstrap._gcd_import(name[level:], package, level)
  File "<frozen importlib._bootstrap>", line 2254, in _gcd_import
  File "<frozen importlib._bootstrap>", line 2237, in _find_and_load
  File "<frozen importlib._bootstrap>", line 2226, in _find_and_load_unlocked
  File "<frozen importlib._bootstrap>", line 1200, in _load_unlocked
  File "<frozen importlib._bootstrap>", line 1129, in _exec
  File "<frozen importlib._bootstrap>", line 1471, in exec_module
  File "<frozen importlib._bootstrap>", line 321, in _call_with_frames_removed
  File "/var/www/django/mysite/urls.py", line 10, in <module>
    url(r'', include('blog.urls')),
  File "/var/www/django/myvenv/lib/python3.4/site-packages/django/conf/urls/__init__.py", line 50, in include
    urlconf_module = import_module(urlconf_module)
  File "/usr/lib/python3.4/importlib/__init__.py", line 109, in import_module
    return _bootstrap._gcd_import(name[level:], package, level)
  File "<frozen importlib._bootstrap>", line 2254, in _gcd_import
  File "<frozen importlib._bootstrap>", line 2237, in _find_and_load
  File "<frozen importlib._bootstrap>", line 2226, in _find_and_load_unlocked
  File "<frozen importlib._bootstrap>", line 1200, in _load_unlocked
  File "<frozen importlib._bootstrap>", line 1129, in _exec
  File "<frozen importlib._bootstrap>", line 1471, in exec_module
  File "<frozen importlib._bootstrap>", line 321, in _call_with_frames_removed
  File "/var/www/django/blog/urls.py", line 2, in <module>
    from . import views
  File "/var/www/django/blog/views.py", line 8
    posts = Post.objects.filter(published_date__lte=timezone.now()).order_by('published_date')
        ^
IndentationError: expected an indented block
Performing system checks...

Unhandled exception in thread started by <function check_errors.<locals>.wrapper at 0x7fbfe7e8a6a8>
Traceback (most recent call last):
  File "/var/www/django/myvenv/lib/python3.4/site-packages/django/utils/autoreload.py", line 228, in wrapper
    fn(*args, **kwargs)
  File "/var/www/django/myvenv/lib/python3.4/site-packages/django/core/management/commands/runserver.py", line 125, in inner_run
    self.check(display_num_errors=True)
  File "/var/www/django/myvenv/lib/python3.4/site-packages/django/core/management/base.py", line 359, in check
    include_deployment_checks=include_deployment_checks,
  File "/var/www/django/myvenv/lib/python3.4/site-packages/django/core/management/base.py", line 346, in _run_checks
    return checks.run_checks(**kwargs)
  File "/var/www/django/myvenv/lib/python3.4/site-packages/django/core/checks/registry.py", line 81, in run_checks
    new_errors = check(app_configs=app_configs)
  File "/var/www/django/myvenv/lib/python3.4/site-packages/django/core/checks/urls.py", line 16, in check_url_config
    return check_resolver(resolver)
  File "/var/www/django/myvenv/lib/python3.4/site-packages/django/core/checks/urls.py", line 26, in check_resolver
    return check_method()
  File "/var/www/django/myvenv/lib/python3.4/site-packages/django/urls/resolvers.py", line 254, in check
    for pattern in self.url_patterns:
  File "/var/www/django/myvenv/lib/python3.4/site-packages/django/utils/functional.py", line 35, in __get__
    res = instance.__dict__[self.name] = self.func(instance)
  File "/var/www/django/myvenv/lib/python3.4/site-packages/django/urls/resolvers.py", line 405, in url_patterns
    patterns = getattr(self.urlconf_module, "urlpatterns", self.urlconf_module)
  File "/var/www/django/myvenv/lib/python3.4/site-packages/django/utils/functional.py", line 35, in __get__
    res = instance.__dict__[self.name] = self.func(instance)
  File "/var/www/django/myvenv/lib/python3.4/site-packages/django/urls/resolvers.py", line 398, in urlconf_module
    return import_module(self.urlconf_name)
  File "/usr/lib/python3.4/importlib/__init__.py", line 109, in import_module
    return _bootstrap._gcd_import(name[level:], package, level)
  File "<frozen importlib._bootstrap>", line 2254, in _gcd_import
  File "<frozen importlib._bootstrap>", line 2237, in _find_and_load
  File "<frozen importlib._bootstrap>", line 2226, in _find_and_load_unlocked
  File "<frozen importlib._bootstrap>", line 1200, in _load_unlocked
  File "<frozen importlib._bootstrap>", line 1129, in _exec
  File "<frozen importlib._bootstrap>", line 1471, in exec_module
  File "<frozen importlib._bootstrap>", line 321, in _call_with_frames_removed
  File "/var/www/django/mysite/urls.py", line 10, in <module>
    url(r'', include('blog.urls')),
  File "/var/www/django/myvenv/lib/python3.4/site-packages/django/conf/urls/__init__.py", line 50, in include
    urlconf_module = import_module(urlconf_module)
  File "/usr/lib/python3.4/importlib/__init__.py", line 109, in import_module
    return _bootstrap._gcd_import(name[level:], package, level)
  File "<frozen importlib._bootstrap>", line 2254, in _gcd_import
  File "<frozen importlib._bootstrap>", line 2237, in _find_and_load
  File "<frozen importlib._bootstrap>", line 2226, in _find_and_load_unlocked
  File "<frozen importlib._bootstrap>", line 1200, in _load_unlocked
  File "<frozen importlib._bootstrap>", line 1129, in _exec
  File "<frozen importlib._bootstrap>", line 1471, in exec_module
  File "<frozen importlib._bootstrap>", line 321, in _call_with_frames_removed
  File "/var/www/django/blog/urls.py", line 2, in <module>
    from . import views
  File "/var/www/django/blog/views.py", line 10
    return render(request, 'blog/post_list.html', {'posts': posts})
    ^
SyntaxError: 'return' outside function
Performing system checks...

[09/Nov/2017 14:49:05] "GET / HTTP/1.1" 200 204
Not Found: /favicon.ico
[09/Nov/2017 14:49:06] "GET /favicon.ico HTTP/1.1" 404 2142
[09/Nov/2017 14:49:08] "GET / HTTP/1.1" 200 204
[09/Nov/2017 14:49:08] "GET / HTTP/1.1" 200 204
[09/Nov/2017 14:49:08] "GET / HTTP/1.1" 200 204
[09/Nov/2017 14:49:08] "GET / HTTP/1.1" 200 204
Performing system checks...

System check identified no issues (0 silenced).
November 09, 2017 - 14:49:05
Django version 1.11.6, using settings 'mysite.settings'
Starting development server at http://192.168.1.123:8000/
Quit the server with CONTROL-C.
Unhandled exception in thread started by <function check_errors.<locals>.wrapper at 0x7fc2fcca06a8>
Traceback (most recent call last):
  File "/var/www/django/myvenv/lib/python3.4/site-packages/django/utils/autoreload.py", line 228, in wrapper
    fn(*args, **kwargs)
  File "/var/www/django/myvenv/lib/python3.4/site-packages/django/core/management/commands/runserver.py", line 125, in inner_run
    self.check(display_num_errors=True)
  File "/var/www/django/myvenv/lib/python3.4/site-packages/django/core/management/base.py", line 359, in check
    include_deployment_checks=include_deployment_checks,
  File "/var/www/django/myvenv/lib/python3.4/site-packages/django/core/management/base.py", line 346, in _run_checks
    return checks.run_checks(**kwargs)
  File "/var/www/django/myvenv/lib/python3.4/site-packages/django/core/checks/registry.py", line 81, in run_checks
    new_errors = check(app_configs=app_configs)
  File "/var/www/django/myvenv/lib/python3.4/site-packages/django/core/checks/urls.py", line 16, in check_url_config
    return check_resolver(resolver)
  File "/var/www/django/myvenv/lib/python3.4/site-packages/django/core/checks/urls.py", line 26, in check_resolver
    return check_method()
  File "/var/www/django/myvenv/lib/python3.4/site-packages/django/urls/resolvers.py", line 254, in check
    for pattern in self.url_patterns:
  File "/var/www/django/myvenv/lib/python3.4/site-packages/django/utils/functional.py", line 35, in __get__
    res = instance.__dict__[self.name] = self.func(instance)
  File "/var/www/django/myvenv/lib/python3.4/site-packages/django/urls/resolvers.py", line 405, in url_patterns
    patterns = getattr(self.urlconf_module, "urlpatterns", self.urlconf_module)
  File "/var/www/django/myvenv/lib/python3.4/site-packages/django/utils/functional.py", line 35, in __get__
    res = instance.__dict__[self.name] = self.func(instance)
  File "/var/www/django/myvenv/lib/python3.4/site-packages/django/urls/resolvers.py", line 398, in urlconf_module
    return import_module(self.urlconf_name)
  File "/usr/lib/python3.4/importlib/__init__.py", line 109, in import_module
    return _bootstrap._gcd_import(name[level:], package, level)
  File "<frozen importlib._bootstrap>", line 2254, in _gcd_import
  File "<frozen importlib._bootstrap>", line 2237, in _find_and_load
  File "<frozen importlib._bootstrap>", line 2226, in _find_and_load_unlocked
  File "<frozen importlib._bootstrap>", line 1200, in _load_unlocked
  File "<frozen importlib._bootstrap>", line 1129, in _exec
  File "<frozen importlib._bootstrap>", line 1471, in exec_module
  File "<frozen importlib._bootstrap>", line 321, in _call_with_frames_removed
  File "/var/www/django/mysite/urls.py", line 10, in <module>
    url(r'', include('blog.urls')),
  File "/var/www/django/myvenv/lib/python3.4/site-packages/django/conf/urls/__init__.py", line 50, in include
    urlconf_module = import_module(urlconf_module)
  File "/usr/lib/python3.4/importlib/__init__.py", line 109, in import_module
    return _bootstrap._gcd_import(name[level:], package, level)
  File "<frozen importlib._bootstrap>", line 2254, in _gcd_import
  File "<frozen importlib._bootstrap>", line 2237, in _find_and_load
  File "<frozen importlib._bootstrap>", line 2226, in _find_and_load_unlocked
  File "<frozen importlib._bootstrap>", line 1200, in _load_unlocked
  File "<frozen importlib._bootstrap>", line 1129, in _exec
  File "<frozen importlib._bootstrap>", line 1471, in exec_module
  File "<frozen importlib._bootstrap>", line 321, in _call_with_frames_removed
  File "/var/www/django/blog/urls.py", line 2, in <module>
    from . import views
  File "/var/www/django/blog/views.py", line 8
    posts = Post.objects.filter(published_date__lte=timezone.now()).order_by('published_date')
        ^
IndentationError: expected an indented block
Performing system checks...

Unhandled exception in thread started by <function check_errors.<locals>.wrapper at 0x7f488ace66a8>
Traceback (most recent call last):
  File "/var/www/django/myvenv/lib/python3.4/site-packages/django/utils/autoreload.py", line 228, in wrapper
    fn(*args, **kwargs)
  File "/var/www/django/myvenv/lib/python3.4/site-packages/django/core/management/commands/runserver.py", line 125, in inner_run
    self.check(display_num_errors=True)
  File "/var/www/django/myvenv/lib/python3.4/site-packages/django/core/management/base.py", line 359, in check
    include_deployment_checks=include_deployment_checks,
  File "/var/www/django/myvenv/lib/python3.4/site-packages/django/core/management/base.py", line 346, in _run_checks
    return checks.run_checks(**kwargs)
  File "/var/www/django/myvenv/lib/python3.4/site-packages/django/core/checks/registry.py", line 81, in run_checks
    new_errors = check(app_configs=app_configs)
  File "/var/www/django/myvenv/lib/python3.4/site-packages/django/core/checks/urls.py", line 16, in check_url_config
    return check_resolver(resolver)
  File "/var/www/django/myvenv/lib/python3.4/site-packages/django/core/checks/urls.py", line 26, in check_resolver
    return check_method()
  File "/var/www/django/myvenv/lib/python3.4/site-packages/django/urls/resolvers.py", line 254, in check
    for pattern in self.url_patterns:
  File "/var/www/django/myvenv/lib/python3.4/site-packages/django/utils/functional.py", line 35, in __get__
    res = instance.__dict__[self.name] = self.func(instance)
  File "/var/www/django/myvenv/lib/python3.4/site-packages/django/urls/resolvers.py", line 405, in url_patterns
    patterns = getattr(self.urlconf_module, "urlpatterns", self.urlconf_module)
  File "/var/www/django/myvenv/lib/python3.4/site-packages/django/utils/functional.py", line 35, in __get__
    res = instance.__dict__[self.name] = self.func(instance)
  File "/var/www/django/myvenv/lib/python3.4/site-packages/django/urls/resolvers.py", line 398, in urlconf_module
    return import_module(self.urlconf_name)
  File "/usr/lib/python3.4/importlib/__init__.py", line 109, in import_module
    return _bootstrap._gcd_import(name[level:], package, level)
  File "<frozen importlib._bootstrap>", line 2254, in _gcd_import
  File "<frozen importlib._bootstrap>", line 2237, in _find_and_load
  File "<frozen importlib._bootstrap>", line 2226, in _find_and_load_unlocked
  File "<frozen importlib._bootstrap>", line 1200, in _load_unlocked
  File "<frozen importlib._bootstrap>", line 1129, in _exec
  File "<frozen importlib._bootstrap>", line 1471, in exec_module
  File "<frozen importlib._bootstrap>", line 321, in _call_with_frames_removed
  File "/var/www/django/mysite/urls.py", line 10, in <module>
    url(r'', include('blog.urls')),
  File "/var/www/django/myvenv/lib/python3.4/site-packages/django/conf/urls/__init__.py", line 50, in include
    urlconf_module = import_module(urlconf_module)
  File "/usr/lib/python3.4/importlib/__init__.py", line 109, in import_module
    return _bootstrap._gcd_import(name[level:], package, level)
  File "<frozen importlib._bootstrap>", line 2254, in _gcd_import
  File "<frozen importlib._bootstrap>", line 2237, in _find_and_load
  File "<frozen importlib._bootstrap>", line 2226, in _find_and_load_unlocked
  File "<frozen importlib._bootstrap>", line 1200, in _load_unlocked
  File "<frozen importlib._bootstrap>", line 1129, in _exec
  File "<frozen importlib._bootstrap>", line 1471, in exec_module
  File "<frozen importlib._bootstrap>", line 321, in _call_with_frames_removed
  File "/var/www/django/blog/urls.py", line 2, in <module>
    from . import views
  File "/var/www/django/blog/views.py", line 8
    posts = Post.objects.filter(published_date__lte=timezone.now()).order_by('published_date')
        ^
IndentationError: expected an indented block
Performing system checks...

Unhandled exception in thread started by <function check_errors.<locals>.wrapper at 0x7fda354416a8>
Traceback (most recent call last):
  File "/var/www/django/myvenv/lib/python3.4/site-packages/django/utils/autoreload.py", line 228, in wrapper
    fn(*args, **kwargs)
  File "/var/www/django/myvenv/lib/python3.4/site-packages/django/core/management/commands/runserver.py", line 125, in inner_run
    self.check(display_num_errors=True)
  File "/var/www/django/myvenv/lib/python3.4/site-packages/django/core/management/base.py", line 359, in check
    include_deployment_checks=include_deployment_checks,
  File "/var/www/django/myvenv/lib/python3.4/site-packages/django/core/management/base.py", line 346, in _run_checks
    return checks.run_checks(**kwargs)
  File "/var/www/django/myvenv/lib/python3.4/site-packages/django/core/checks/registry.py", line 81, in run_checks
    new_errors = check(app_configs=app_configs)
  File "/var/www/django/myvenv/lib/python3.4/site-packages/django/core/checks/urls.py", line 16, in check_url_config
    return check_resolver(resolver)
  File "/var/www/django/myvenv/lib/python3.4/site-packages/django/core/checks/urls.py", line 26, in check_resolver
    return check_method()
  File "/var/www/django/myvenv/lib/python3.4/site-packages/django/urls/resolvers.py", line 254, in check
    for pattern in self.url_patterns:
  File "/var/www/django/myvenv/lib/python3.4/site-packages/django/utils/functional.py", line 35, in __get__
    res = instance.__dict__[self.name] = self.func(instance)
  File "/var/www/django/myvenv/lib/python3.4/site-packages/django/urls/resolvers.py", line 405, in url_patterns
    patterns = getattr(self.urlconf_module, "urlpatterns", self.urlconf_module)
  File "/var/www/django/myvenv/lib/python3.4/site-packages/django/utils/functional.py", line 35, in __get__
    res = instance.__dict__[self.name] = self.func(instance)
  File "/var/www/django/myvenv/lib/python3.4/site-packages/django/urls/resolvers.py", line 398, in urlconf_module
    return import_module(self.urlconf_name)
  File "/usr/lib/python3.4/importlib/__init__.py", line 109, in import_module
    return _bootstrap._gcd_import(name[level:], package, level)
  File "<frozen importlib._bootstrap>", line 2254, in _gcd_import
  File "<frozen importlib._bootstrap>", line 2237, in _find_and_load
  File "<frozen importlib._bootstrap>", line 2226, in _find_and_load_unlocked
  File "<frozen importlib._bootstrap>", line 1200, in _load_unlocked
  File "<frozen importlib._bootstrap>", line 1129, in _exec
  File "<frozen importlib._bootstrap>", line 1471, in exec_module
  File "<frozen importlib._bootstrap>", line 321, in _call_with_frames_removed
  File "/var/www/django/mysite/urls.py", line 10, in <module>
    url(r'', include('blog.urls')),
  File "/var/www/django/myvenv/lib/python3.4/site-packages/django/conf/urls/__init__.py", line 50, in include
    urlconf_module = import_module(urlconf_module)
  File "/usr/lib/python3.4/importlib/__init__.py", line 109, in import_module
    return _bootstrap._gcd_import(name[level:], package, level)
  File "<frozen importlib._bootstrap>", line 2254, in _gcd_import
  File "<frozen importlib._bootstrap>", line 2237, in _find_and_load
  File "<frozen importlib._bootstrap>", line 2226, in _find_and_load_unlocked
  File "<frozen importlib._bootstrap>", line 1200, in _load_unlocked
  File "<frozen importlib._bootstrap>", line 1129, in _exec
  File "<frozen importlib._bootstrap>", line 1471, in exec_module
  File "<frozen importlib._bootstrap>", line 321, in _call_with_frames_removed
  File "/var/www/django/blog/urls.py", line 2, in <module>
    from . import views
  File "/var/www/django/blog/views.py", line 8
    posts = Post.objects.filter(published_date__lte=timezone.now()).order_by('published_date')
        ^
IndentationError: expected an indented block
Performing system checks...

[09/Nov/2017 14:52:33] "GET /admin/ HTTP/1.1" 200 5283
Not Found: /favicon.ico
[09/Nov/2017 14:52:34] "GET /favicon.ico HTTP/1.1" 404 2142
[09/Nov/2017 14:52:40] "GET / HTTP/1.1" 200 204
Performing system checks...

System check identified no issues (0 silenced).
November 09, 2017 - 14:52:32
Django version 1.11.6, using settings 'mysite.settings'
Starting development server at http://192.168.1.123:8000/
Quit the server with CONTROL-C.
[09/Nov/2017 14:58:15] "GET / HTTP/1.1" 200 424
Not Found: /favicon.ico
[09/Nov/2017 14:58:15] "GET /favicon.ico HTTP/1.1" 404 2142
[09/Nov/2017 15:02:28] "GET / HTTP/1.1" 200 357
[09/Nov/2017 15:04:18] "GET / HTTP/1.1" 200 4263
[09/Nov/2017 15:04:47] "GET / HTTP/1.1" 200 4263
[09/Nov/2017 15:04:48] "GET / HTTP/1.1" 200 4263
[09/Nov/2017 15:04:49] "GET / HTTP/1.1" 200 4263
[09/Nov/2017 15:09:39] "GET / HTTP/1.1" 200 4263
[09/Nov/2017 15:09:41] "GET / HTTP/1.1" 200 4263
[09/Nov/2017 15:10:30] "GET / HTTP/1.1" 200 4263
[09/Nov/2017 15:10:31] "GET / HTTP/1.1" 200 4263
[09/Nov/2017 15:10:33] "GET /admin/ HTTP/1.1" 200 5283
